ERROR 2025-06-02 08:06:27,524 log 10664 19400 Internal Server Error: /admin/core/cycle/add/
Traceback (most recent call last):
  File "C:\Users\tefba\Desktop\OverBrand\acadflow\acadflow_env\Lib\site-packages\django\db\backends\utils.py", line 105, in _execute
    return self.cursor.execute(sql, params)
           ~~~~~~~~~~~~~~~~~~~^^^^^^^^^^^^^
psycopg2.errors.UndefinedTable: ERREUR:  la relation « users » n'existe pas
LINE 1: ...naissance", "users"."photo", "users"."actif" FROM "users" WH...
                                                             ^


The above exception was the direct cause of the following exception:

Traceback (most recent call last):
  File "C:\Users\tefba\Desktop\OverBrand\acadflow\acadflow_env\Lib\site-packages\django\core\handlers\exception.py", line 55, in inner
    response = get_response(request)
  File "C:\Users\tefba\Desktop\OverBrand\acadflow\acadflow_env\Lib\site-packages\django\core\handlers\base.py", line 197, in _get_response
    response = wrapped_callback(request, *callback_args, **callback_kwargs)
  File "C:\Users\tefba\Desktop\OverBrand\acadflow\acadflow_env\Lib\site-packages\django\contrib\admin\options.py", line 719, in wrapper
    return self.admin_site.admin_view(view)(*args, **kwargs)
           ~~~~~~~~~~~~~~~~~~~~~~~~~~~~~~~~^^^^^^^^^^^^^^^^^
  File "C:\Users\tefba\Desktop\OverBrand\acadflow\acadflow_env\Lib\site-packages\django\utils\decorators.py", line 192, in _view_wrapper
    result = _process_exception(request, e)
  File "C:\Users\tefba\Desktop\OverBrand\acadflow\acadflow_env\Lib\site-packages\django\utils\decorators.py", line 190, in _view_wrapper
    response = view_func(request, *args, **kwargs)
  File "C:\Users\tefba\Desktop\OverBrand\acadflow\acadflow_env\Lib\site-packages\django\views\decorators\cache.py", line 80, in _view_wrapper
    response = view_func(request, *args, **kwargs)
  File "C:\Users\tefba\Desktop\OverBrand\acadflow\acadflow_env\Lib\site-packages\django\contrib\admin\sites.py", line 234, in inner
    if not self.has_permission(request):
           ~~~~~~~~~~~~~~~~~~~^^^^^^^^^
  File "C:\Users\tefba\Desktop\OverBrand\acadflow\acadflow_env\Lib\site-packages\django\contrib\admin\sites.py", line 207, in has_permission
    return request.user.is_active and request.user.is_staff
           ^^^^^^^^^^^^^^^^^^^^^^
  File "C:\Users\tefba\Desktop\OverBrand\acadflow\acadflow_env\Lib\site-packages\django\utils\functional.py", line 251, in inner
    self._setup()
    ~~~~~~~~~~~^^
  File "C:\Users\tefba\Desktop\OverBrand\acadflow\acadflow_env\Lib\site-packages\django\utils\functional.py", line 404, in _setup
    self._wrapped = self._setupfunc()
                    ~~~~~~~~~~~~~~~^^
  File "C:\Users\tefba\Desktop\OverBrand\acadflow\acadflow_env\Lib\site-packages\django\contrib\auth\middleware.py", line 39, in <lambda>
    request.user = SimpleLazyObject(lambda: get_user(request))
                                            ~~~~~~~~^^^^^^^^^
  File "C:\Users\tefba\Desktop\OverBrand\acadflow\acadflow_env\Lib\site-packages\django\contrib\auth\middleware.py", line 19, in get_user
    request._cached_user = auth.get_user(request)
                           ~~~~~~~~~~~~~^^^^^^^^^
  File "C:\Users\tefba\Desktop\OverBrand\acadflow\acadflow_env\Lib\site-packages\django\contrib\auth\__init__.py", line 311, in get_user
    user = backend.get_user(user_id)
  File "C:\Users\tefba\Desktop\OverBrand\acadflow\acadflow_env\Lib\site-packages\django\contrib\auth\backends.py", line 232, in get_user
    user = UserModel._default_manager.get(pk=user_id)
  File "C:\Users\tefba\Desktop\OverBrand\acadflow\acadflow_env\Lib\site-packages\django\db\models\manager.py", line 87, in manager_method
    return getattr(self.get_queryset(), name)(*args, **kwargs)
           ~~~~~~~~~~~~~~~~~~~~~~~~~~~~~~~~~~^^^^^^^^^^^^^^^^^
  File "C:\Users\tefba\Desktop\OverBrand\acadflow\acadflow_env\Lib\site-packages\django\db\models\query.py", line 629, in get
    num = len(clone)
  File "C:\Users\tefba\Desktop\OverBrand\acadflow\acadflow_env\Lib\site-packages\django\db\models\query.py", line 366, in __len__
    self._fetch_all()
    ~~~~~~~~~~~~~~~^^
  File "C:\Users\tefba\Desktop\OverBrand\acadflow\acadflow_env\Lib\site-packages\django\db\models\query.py", line 1945, in _fetch_all
    self._result_cache = list(self._iterable_class(self))
                         ~~~~^^^^^^^^^^^^^^^^^^^^^^^^^^^^
  File "C:\Users\tefba\Desktop\OverBrand\acadflow\acadflow_env\Lib\site-packages\django\db\models\query.py", line 91, in __iter__
    results = compiler.execute_sql(
        chunked_fetch=self.chunked_fetch, chunk_size=self.chunk_size
    )
  File "C:\Users\tefba\Desktop\OverBrand\acadflow\acadflow_env\Lib\site-packages\django\db\models\sql\compiler.py", line 1623, in execute_sql
    cursor.execute(sql, params)
    ~~~~~~~~~~~~~~^^^^^^^^^^^^^
  File "C:\Users\tefba\Desktop\OverBrand\acadflow\acadflow_env\Lib\site-packages\django\db\backends\utils.py", line 122, in execute
    return super().execute(sql, params)
           ~~~~~~~~~~~~~~~^^^^^^^^^^^^^
  File "C:\Users\tefba\Desktop\OverBrand\acadflow\acadflow_env\Lib\site-packages\django\db\backends\utils.py", line 79, in execute
    return self._execute_with_wrappers(
           ~~~~~~~~~~~~~~~~~~~~~~~~~~~^
        sql, params, many=False, executor=self._execute
        ^^^^^^^^^^^^^^^^^^^^^^^^^^^^^^^^^^^^^^^^^^^^^^^
    )
    ^
  File "C:\Users\tefba\Desktop\OverBrand\acadflow\acadflow_env\Lib\site-packages\django\db\backends\utils.py", line 92, in _execute_with_wrappers
    return executor(sql, params, many, context)
  File "C:\Users\tefba\Desktop\OverBrand\acadflow\acadflow_env\Lib\site-packages\django\db\backends\utils.py", line 100, in _execute
    with self.db.wrap_database_errors:
         ^^^^^^^^^^^^^^^^^^^^^^^^^^^^
  File "C:\Users\tefba\Desktop\OverBrand\acadflow\acadflow_env\Lib\site-packages\django\db\utils.py", line 91, in __exit__
    raise dj_exc_value.with_traceback(traceback) from exc_value
  File "C:\Users\tefba\Desktop\OverBrand\acadflow\acadflow_env\Lib\site-packages\django\db\backends\utils.py", line 105, in _execute
    return self.cursor.execute(sql, params)
           ~~~~~~~~~~~~~~~~~~~^^^^^^^^^^^^^
django.db.utils.ProgrammingError: ERREUR:  la relation « users » n'existe pas
LINE 1: ...naissance", "users"."photo", "users"."actif" FROM "users" WH...
                                                             ^

ERROR 2025-06-02 08:06:27,529 basehttp 10664 19400 "POST /admin/core/cycle/add/ HTTP/1.1" 500 194714
ERROR 2025-06-02 08:06:30,824 log 10664 19400 Internal Server Error: /admin/core/cycle/add/
Traceback (most recent call last):
  File "C:\Users\tefba\Desktop\OverBrand\acadflow\acadflow_env\Lib\site-packages\django\db\backends\utils.py", line 105, in _execute
    return self.cursor.execute(sql, params)
           ~~~~~~~~~~~~~~~~~~~^^^^^^^^^^^^^
psycopg2.errors.UndefinedTable: ERREUR:  la relation « users » n'existe pas
LINE 1: ...naissance", "users"."photo", "users"."actif" FROM "users" WH...
                                                             ^


The above exception was the direct cause of the following exception:

Traceback (most recent call last):
  File "C:\Users\tefba\Desktop\OverBrand\acadflow\acadflow_env\Lib\site-packages\django\core\handlers\exception.py", line 55, in inner
    response = get_response(request)
  File "C:\Users\tefba\Desktop\OverBrand\acadflow\acadflow_env\Lib\site-packages\django\core\handlers\base.py", line 197, in _get_response
    response = wrapped_callback(request, *callback_args, **callback_kwargs)
  File "C:\Users\tefba\Desktop\OverBrand\acadflow\acadflow_env\Lib\site-packages\django\contrib\admin\options.py", line 719, in wrapper
    return self.admin_site.admin_view(view)(*args, **kwargs)
           ~~~~~~~~~~~~~~~~~~~~~~~~~~~~~~~~^^^^^^^^^^^^^^^^^
  File "C:\Users\tefba\Desktop\OverBrand\acadflow\acadflow_env\Lib\site-packages\django\utils\decorators.py", line 192, in _view_wrapper
    result = _process_exception(request, e)
  File "C:\Users\tefba\Desktop\OverBrand\acadflow\acadflow_env\Lib\site-packages\django\utils\decorators.py", line 190, in _view_wrapper
    response = view_func(request, *args, **kwargs)
  File "C:\Users\tefba\Desktop\OverBrand\acadflow\acadflow_env\Lib\site-packages\django\views\decorators\cache.py", line 80, in _view_wrapper
    response = view_func(request, *args, **kwargs)
  File "C:\Users\tefba\Desktop\OverBrand\acadflow\acadflow_env\Lib\site-packages\django\contrib\admin\sites.py", line 234, in inner
    if not self.has_permission(request):
           ~~~~~~~~~~~~~~~~~~~^^^^^^^^^
  File "C:\Users\tefba\Desktop\OverBrand\acadflow\acadflow_env\Lib\site-packages\django\contrib\admin\sites.py", line 207, in has_permission
    return request.user.is_active and request.user.is_staff
           ^^^^^^^^^^^^^^^^^^^^^^
  File "C:\Users\tefba\Desktop\OverBrand\acadflow\acadflow_env\Lib\site-packages\django\utils\functional.py", line 251, in inner
    self._setup()
    ~~~~~~~~~~~^^
  File "C:\Users\tefba\Desktop\OverBrand\acadflow\acadflow_env\Lib\site-packages\django\utils\functional.py", line 404, in _setup
    self._wrapped = self._setupfunc()
                    ~~~~~~~~~~~~~~~^^
  File "C:\Users\tefba\Desktop\OverBrand\acadflow\acadflow_env\Lib\site-packages\django\contrib\auth\middleware.py", line 39, in <lambda>
    request.user = SimpleLazyObject(lambda: get_user(request))
                                            ~~~~~~~~^^^^^^^^^
  File "C:\Users\tefba\Desktop\OverBrand\acadflow\acadflow_env\Lib\site-packages\django\contrib\auth\middleware.py", line 19, in get_user
    request._cached_user = auth.get_user(request)
                           ~~~~~~~~~~~~~^^^^^^^^^
  File "C:\Users\tefba\Desktop\OverBrand\acadflow\acadflow_env\Lib\site-packages\django\contrib\auth\__init__.py", line 311, in get_user
    user = backend.get_user(user_id)
  File "C:\Users\tefba\Desktop\OverBrand\acadflow\acadflow_env\Lib\site-packages\django\contrib\auth\backends.py", line 232, in get_user
    user = UserModel._default_manager.get(pk=user_id)
  File "C:\Users\tefba\Desktop\OverBrand\acadflow\acadflow_env\Lib\site-packages\django\db\models\manager.py", line 87, in manager_method
    return getattr(self.get_queryset(), name)(*args, **kwargs)
           ~~~~~~~~~~~~~~~~~~~~~~~~~~~~~~~~~~^^^^^^^^^^^^^^^^^
  File "C:\Users\tefba\Desktop\OverBrand\acadflow\acadflow_env\Lib\site-packages\django\db\models\query.py", line 629, in get
    num = len(clone)
  File "C:\Users\tefba\Desktop\OverBrand\acadflow\acadflow_env\Lib\site-packages\django\db\models\query.py", line 366, in __len__
    self._fetch_all()
    ~~~~~~~~~~~~~~~^^
  File "C:\Users\tefba\Desktop\OverBrand\acadflow\acadflow_env\Lib\site-packages\django\db\models\query.py", line 1945, in _fetch_all
    self._result_cache = list(self._iterable_class(self))
                         ~~~~^^^^^^^^^^^^^^^^^^^^^^^^^^^^
  File "C:\Users\tefba\Desktop\OverBrand\acadflow\acadflow_env\Lib\site-packages\django\db\models\query.py", line 91, in __iter__
    results = compiler.execute_sql(
        chunked_fetch=self.chunked_fetch, chunk_size=self.chunk_size
    )
  File "C:\Users\tefba\Desktop\OverBrand\acadflow\acadflow_env\Lib\site-packages\django\db\models\sql\compiler.py", line 1623, in execute_sql
    cursor.execute(sql, params)
    ~~~~~~~~~~~~~~^^^^^^^^^^^^^
  File "C:\Users\tefba\Desktop\OverBrand\acadflow\acadflow_env\Lib\site-packages\django\db\backends\utils.py", line 122, in execute
    return super().execute(sql, params)
           ~~~~~~~~~~~~~~~^^^^^^^^^^^^^
  File "C:\Users\tefba\Desktop\OverBrand\acadflow\acadflow_env\Lib\site-packages\django\db\backends\utils.py", line 79, in execute
    return self._execute_with_wrappers(
           ~~~~~~~~~~~~~~~~~~~~~~~~~~~^
        sql, params, many=False, executor=self._execute
        ^^^^^^^^^^^^^^^^^^^^^^^^^^^^^^^^^^^^^^^^^^^^^^^
    )
    ^
  File "C:\Users\tefba\Desktop\OverBrand\acadflow\acadflow_env\Lib\site-packages\django\db\backends\utils.py", line 92, in _execute_with_wrappers
    return executor(sql, params, many, context)
  File "C:\Users\tefba\Desktop\OverBrand\acadflow\acadflow_env\Lib\site-packages\django\db\backends\utils.py", line 100, in _execute
    with self.db.wrap_database_errors:
         ^^^^^^^^^^^^^^^^^^^^^^^^^^^^
  File "C:\Users\tefba\Desktop\OverBrand\acadflow\acadflow_env\Lib\site-packages\django\db\utils.py", line 91, in __exit__
    raise dj_exc_value.with_traceback(traceback) from exc_value
  File "C:\Users\tefba\Desktop\OverBrand\acadflow\acadflow_env\Lib\site-packages\django\db\backends\utils.py", line 105, in _execute
    return self.cursor.execute(sql, params)
           ~~~~~~~~~~~~~~~~~~~^^^^^^^^^^^^^
django.db.utils.ProgrammingError: ERREUR:  la relation « users » n'existe pas
LINE 1: ...naissance", "users"."photo", "users"."actif" FROM "users" WH...
                                                             ^

ERROR 2025-06-02 08:06:30,831 basehttp 10664 19400 "POST /admin/core/cycle/add/ HTTP/1.1" 500 194714
ERROR 2025-06-02 08:06:33,812 log 10664 19400 Internal Server Error: /admin/core/cycle/add/
Traceback (most recent call last):
  File "C:\Users\tefba\Desktop\OverBrand\acadflow\acadflow_env\Lib\site-packages\django\db\backends\utils.py", line 105, in _execute
    return self.cursor.execute(sql, params)
           ~~~~~~~~~~~~~~~~~~~^^^^^^^^^^^^^
psycopg2.errors.UndefinedTable: ERREUR:  la relation « users » n'existe pas
LINE 1: ...naissance", "users"."photo", "users"."actif" FROM "users" WH...
                                                             ^


The above exception was the direct cause of the following exception:

Traceback (most recent call last):
  File "C:\Users\tefba\Desktop\OverBrand\acadflow\acadflow_env\Lib\site-packages\django\core\handlers\exception.py", line 55, in inner
    response = get_response(request)
  File "C:\Users\tefba\Desktop\OverBrand\acadflow\acadflow_env\Lib\site-packages\django\core\handlers\base.py", line 197, in _get_response
    response = wrapped_callback(request, *callback_args, **callback_kwargs)
  File "C:\Users\tefba\Desktop\OverBrand\acadflow\acadflow_env\Lib\site-packages\django\contrib\admin\options.py", line 719, in wrapper
    return self.admin_site.admin_view(view)(*args, **kwargs)
           ~~~~~~~~~~~~~~~~~~~~~~~~~~~~~~~~^^^^^^^^^^^^^^^^^
  File "C:\Users\tefba\Desktop\OverBrand\acadflow\acadflow_env\Lib\site-packages\django\utils\decorators.py", line 192, in _view_wrapper
    result = _process_exception(request, e)
  File "C:\Users\tefba\Desktop\OverBrand\acadflow\acadflow_env\Lib\site-packages\django\utils\decorators.py", line 190, in _view_wrapper
    response = view_func(request, *args, **kwargs)
  File "C:\Users\tefba\Desktop\OverBrand\acadflow\acadflow_env\Lib\site-packages\django\views\decorators\cache.py", line 80, in _view_wrapper
    response = view_func(request, *args, **kwargs)
  File "C:\Users\tefba\Desktop\OverBrand\acadflow\acadflow_env\Lib\site-packages\django\contrib\admin\sites.py", line 234, in inner
    if not self.has_permission(request):
           ~~~~~~~~~~~~~~~~~~~^^^^^^^^^
  File "C:\Users\tefba\Desktop\OverBrand\acadflow\acadflow_env\Lib\site-packages\django\contrib\admin\sites.py", line 207, in has_permission
    return request.user.is_active and request.user.is_staff
           ^^^^^^^^^^^^^^^^^^^^^^
  File "C:\Users\tefba\Desktop\OverBrand\acadflow\acadflow_env\Lib\site-packages\django\utils\functional.py", line 251, in inner
    self._setup()
    ~~~~~~~~~~~^^
  File "C:\Users\tefba\Desktop\OverBrand\acadflow\acadflow_env\Lib\site-packages\django\utils\functional.py", line 404, in _setup
    self._wrapped = self._setupfunc()
                    ~~~~~~~~~~~~~~~^^
  File "C:\Users\tefba\Desktop\OverBrand\acadflow\acadflow_env\Lib\site-packages\django\contrib\auth\middleware.py", line 39, in <lambda>
    request.user = SimpleLazyObject(lambda: get_user(request))
                                            ~~~~~~~~^^^^^^^^^
  File "C:\Users\tefba\Desktop\OverBrand\acadflow\acadflow_env\Lib\site-packages\django\contrib\auth\middleware.py", line 19, in get_user
    request._cached_user = auth.get_user(request)
                           ~~~~~~~~~~~~~^^^^^^^^^
  File "C:\Users\tefba\Desktop\OverBrand\acadflow\acadflow_env\Lib\site-packages\django\contrib\auth\__init__.py", line 311, in get_user
    user = backend.get_user(user_id)
  File "C:\Users\tefba\Desktop\OverBrand\acadflow\acadflow_env\Lib\site-packages\django\contrib\auth\backends.py", line 232, in get_user
    user = UserModel._default_manager.get(pk=user_id)
  File "C:\Users\tefba\Desktop\OverBrand\acadflow\acadflow_env\Lib\site-packages\django\db\models\manager.py", line 87, in manager_method
    return getattr(self.get_queryset(), name)(*args, **kwargs)
           ~~~~~~~~~~~~~~~~~~~~~~~~~~~~~~~~~~^^^^^^^^^^^^^^^^^
  File "C:\Users\tefba\Desktop\OverBrand\acadflow\acadflow_env\Lib\site-packages\django\db\models\query.py", line 629, in get
    num = len(clone)
  File "C:\Users\tefba\Desktop\OverBrand\acadflow\acadflow_env\Lib\site-packages\django\db\models\query.py", line 366, in __len__
    self._fetch_all()
    ~~~~~~~~~~~~~~~^^
  File "C:\Users\tefba\Desktop\OverBrand\acadflow\acadflow_env\Lib\site-packages\django\db\models\query.py", line 1945, in _fetch_all
    self._result_cache = list(self._iterable_class(self))
                         ~~~~^^^^^^^^^^^^^^^^^^^^^^^^^^^^
  File "C:\Users\tefba\Desktop\OverBrand\acadflow\acadflow_env\Lib\site-packages\django\db\models\query.py", line 91, in __iter__
    results = compiler.execute_sql(
        chunked_fetch=self.chunked_fetch, chunk_size=self.chunk_size
    )
  File "C:\Users\tefba\Desktop\OverBrand\acadflow\acadflow_env\Lib\site-packages\django\db\models\sql\compiler.py", line 1623, in execute_sql
    cursor.execute(sql, params)
    ~~~~~~~~~~~~~~^^^^^^^^^^^^^
  File "C:\Users\tefba\Desktop\OverBrand\acadflow\acadflow_env\Lib\site-packages\django\db\backends\utils.py", line 122, in execute
    return super().execute(sql, params)
           ~~~~~~~~~~~~~~~^^^^^^^^^^^^^
  File "C:\Users\tefba\Desktop\OverBrand\acadflow\acadflow_env\Lib\site-packages\django\db\backends\utils.py", line 79, in execute
    return self._execute_with_wrappers(
           ~~~~~~~~~~~~~~~~~~~~~~~~~~~^
        sql, params, many=False, executor=self._execute
        ^^^^^^^^^^^^^^^^^^^^^^^^^^^^^^^^^^^^^^^^^^^^^^^
    )
    ^
  File "C:\Users\tefba\Desktop\OverBrand\acadflow\acadflow_env\Lib\site-packages\django\db\backends\utils.py", line 92, in _execute_with_wrappers
    return executor(sql, params, many, context)
  File "C:\Users\tefba\Desktop\OverBrand\acadflow\acadflow_env\Lib\site-packages\django\db\backends\utils.py", line 100, in _execute
    with self.db.wrap_database_errors:
         ^^^^^^^^^^^^^^^^^^^^^^^^^^^^
  File "C:\Users\tefba\Desktop\OverBrand\acadflow\acadflow_env\Lib\site-packages\django\db\utils.py", line 91, in __exit__
    raise dj_exc_value.with_traceback(traceback) from exc_value
  File "C:\Users\tefba\Desktop\OverBrand\acadflow\acadflow_env\Lib\site-packages\django\db\backends\utils.py", line 105, in _execute
    return self.cursor.execute(sql, params)
           ~~~~~~~~~~~~~~~~~~~^^^^^^^^^^^^^
django.db.utils.ProgrammingError: ERREUR:  la relation « users » n'existe pas
LINE 1: ...naissance", "users"."photo", "users"."actif" FROM "users" WH...
                                                             ^

ERROR 2025-06-02 08:06:33,819 basehttp 10664 19400 "GET /admin/core/cycle/add/ HTTP/1.1" 500 193218
ERROR 2025-06-02 08:06:34,752 log 10664 19400 Internal Server Error: /admin/core/cycle/
Traceback (most recent call last):
  File "C:\Users\tefba\Desktop\OverBrand\acadflow\acadflow_env\Lib\site-packages\django\db\backends\utils.py", line 105, in _execute
    return self.cursor.execute(sql, params)
           ~~~~~~~~~~~~~~~~~~~^^^^^^^^^^^^^
psycopg2.errors.UndefinedTable: ERREUR:  la relation « users » n'existe pas
LINE 1: ...naissance", "users"."photo", "users"."actif" FROM "users" WH...
                                                             ^


The above exception was the direct cause of the following exception:

Traceback (most recent call last):
  File "C:\Users\tefba\Desktop\OverBrand\acadflow\acadflow_env\Lib\site-packages\django\core\handlers\exception.py", line 55, in inner
    response = get_response(request)
  File "C:\Users\tefba\Desktop\OverBrand\acadflow\acadflow_env\Lib\site-packages\django\core\handlers\base.py", line 197, in _get_response
    response = wrapped_callback(request, *callback_args, **callback_kwargs)
  File "C:\Users\tefba\Desktop\OverBrand\acadflow\acadflow_env\Lib\site-packages\django\contrib\admin\options.py", line 719, in wrapper
    return self.admin_site.admin_view(view)(*args, **kwargs)
           ~~~~~~~~~~~~~~~~~~~~~~~~~~~~~~~~^^^^^^^^^^^^^^^^^
  File "C:\Users\tefba\Desktop\OverBrand\acadflow\acadflow_env\Lib\site-packages\django\utils\decorators.py", line 192, in _view_wrapper
    result = _process_exception(request, e)
  File "C:\Users\tefba\Desktop\OverBrand\acadflow\acadflow_env\Lib\site-packages\django\utils\decorators.py", line 190, in _view_wrapper
    response = view_func(request, *args, **kwargs)
  File "C:\Users\tefba\Desktop\OverBrand\acadflow\acadflow_env\Lib\site-packages\django\views\decorators\cache.py", line 80, in _view_wrapper
    response = view_func(request, *args, **kwargs)
  File "C:\Users\tefba\Desktop\OverBrand\acadflow\acadflow_env\Lib\site-packages\django\contrib\admin\sites.py", line 234, in inner
    if not self.has_permission(request):
           ~~~~~~~~~~~~~~~~~~~^^^^^^^^^
  File "C:\Users\tefba\Desktop\OverBrand\acadflow\acadflow_env\Lib\site-packages\django\contrib\admin\sites.py", line 207, in has_permission
    return request.user.is_active and request.user.is_staff
           ^^^^^^^^^^^^^^^^^^^^^^
  File "C:\Users\tefba\Desktop\OverBrand\acadflow\acadflow_env\Lib\site-packages\django\utils\functional.py", line 251, in inner
    self._setup()
    ~~~~~~~~~~~^^
  File "C:\Users\tefba\Desktop\OverBrand\acadflow\acadflow_env\Lib\site-packages\django\utils\functional.py", line 404, in _setup
    self._wrapped = self._setupfunc()
                    ~~~~~~~~~~~~~~~^^
  File "C:\Users\tefba\Desktop\OverBrand\acadflow\acadflow_env\Lib\site-packages\django\contrib\auth\middleware.py", line 39, in <lambda>
    request.user = SimpleLazyObject(lambda: get_user(request))
                                            ~~~~~~~~^^^^^^^^^
  File "C:\Users\tefba\Desktop\OverBrand\acadflow\acadflow_env\Lib\site-packages\django\contrib\auth\middleware.py", line 19, in get_user
    request._cached_user = auth.get_user(request)
                           ~~~~~~~~~~~~~^^^^^^^^^
  File "C:\Users\tefba\Desktop\OverBrand\acadflow\acadflow_env\Lib\site-packages\django\contrib\auth\__init__.py", line 311, in get_user
    user = backend.get_user(user_id)
  File "C:\Users\tefba\Desktop\OverBrand\acadflow\acadflow_env\Lib\site-packages\django\contrib\auth\backends.py", line 232, in get_user
    user = UserModel._default_manager.get(pk=user_id)
  File "C:\Users\tefba\Desktop\OverBrand\acadflow\acadflow_env\Lib\site-packages\django\db\models\manager.py", line 87, in manager_method
    return getattr(self.get_queryset(), name)(*args, **kwargs)
           ~~~~~~~~~~~~~~~~~~~~~~~~~~~~~~~~~~^^^^^^^^^^^^^^^^^
  File "C:\Users\tefba\Desktop\OverBrand\acadflow\acadflow_env\Lib\site-packages\django\db\models\query.py", line 629, in get
    num = len(clone)
  File "C:\Users\tefba\Desktop\OverBrand\acadflow\acadflow_env\Lib\site-packages\django\db\models\query.py", line 366, in __len__
    self._fetch_all()
    ~~~~~~~~~~~~~~~^^
  File "C:\Users\tefba\Desktop\OverBrand\acadflow\acadflow_env\Lib\site-packages\django\db\models\query.py", line 1945, in _fetch_all
    self._result_cache = list(self._iterable_class(self))
                         ~~~~^^^^^^^^^^^^^^^^^^^^^^^^^^^^
  File "C:\Users\tefba\Desktop\OverBrand\acadflow\acadflow_env\Lib\site-packages\django\db\models\query.py", line 91, in __iter__
    results = compiler.execute_sql(
        chunked_fetch=self.chunked_fetch, chunk_size=self.chunk_size
    )
  File "C:\Users\tefba\Desktop\OverBrand\acadflow\acadflow_env\Lib\site-packages\django\db\models\sql\compiler.py", line 1623, in execute_sql
    cursor.execute(sql, params)
    ~~~~~~~~~~~~~~^^^^^^^^^^^^^
  File "C:\Users\tefba\Desktop\OverBrand\acadflow\acadflow_env\Lib\site-packages\django\db\backends\utils.py", line 122, in execute
    return super().execute(sql, params)
           ~~~~~~~~~~~~~~~^^^^^^^^^^^^^
  File "C:\Users\tefba\Desktop\OverBrand\acadflow\acadflow_env\Lib\site-packages\django\db\backends\utils.py", line 79, in execute
    return self._execute_with_wrappers(
           ~~~~~~~~~~~~~~~~~~~~~~~~~~~^
        sql, params, many=False, executor=self._execute
        ^^^^^^^^^^^^^^^^^^^^^^^^^^^^^^^^^^^^^^^^^^^^^^^
    )
    ^
  File "C:\Users\tefba\Desktop\OverBrand\acadflow\acadflow_env\Lib\site-packages\django\db\backends\utils.py", line 92, in _execute_with_wrappers
    return executor(sql, params, many, context)
  File "C:\Users\tefba\Desktop\OverBrand\acadflow\acadflow_env\Lib\site-packages\django\db\backends\utils.py", line 100, in _execute
    with self.db.wrap_database_errors:
         ^^^^^^^^^^^^^^^^^^^^^^^^^^^^
  File "C:\Users\tefba\Desktop\OverBrand\acadflow\acadflow_env\Lib\site-packages\django\db\utils.py", line 91, in __exit__
    raise dj_exc_value.with_traceback(traceback) from exc_value
  File "C:\Users\tefba\Desktop\OverBrand\acadflow\acadflow_env\Lib\site-packages\django\db\backends\utils.py", line 105, in _execute
    return self.cursor.execute(sql, params)
           ~~~~~~~~~~~~~~~~~~~^^^^^^^^^^^^^
django.db.utils.ProgrammingError: ERREUR:  la relation « users » n'existe pas
LINE 1: ...naissance", "users"."photo", "users"."actif" FROM "users" WH...
                                                             ^

ERROR 2025-06-02 08:06:34,758 basehttp 10664 19400 "GET /admin/core/cycle/ HTTP/1.1" 500 193181
ERROR 2025-06-02 08:06:36,911 log 10664 19400 Internal Server Error: /admin/core/niveau/add/
Traceback (most recent call last):
  File "C:\Users\tefba\Desktop\OverBrand\acadflow\acadflow_env\Lib\site-packages\django\db\backends\utils.py", line 105, in _execute
    return self.cursor.execute(sql, params)
           ~~~~~~~~~~~~~~~~~~~^^^^^^^^^^^^^
psycopg2.errors.UndefinedTable: ERREUR:  la relation « users » n'existe pas
LINE 1: ...naissance", "users"."photo", "users"."actif" FROM "users" WH...
                                                             ^


The above exception was the direct cause of the following exception:

Traceback (most recent call last):
  File "C:\Users\tefba\Desktop\OverBrand\acadflow\acadflow_env\Lib\site-packages\django\core\handlers\exception.py", line 55, in inner
    response = get_response(request)
  File "C:\Users\tefba\Desktop\OverBrand\acadflow\acadflow_env\Lib\site-packages\django\core\handlers\base.py", line 197, in _get_response
    response = wrapped_callback(request, *callback_args, **callback_kwargs)
  File "C:\Users\tefba\Desktop\OverBrand\acadflow\acadflow_env\Lib\site-packages\django\contrib\admin\options.py", line 719, in wrapper
    return self.admin_site.admin_view(view)(*args, **kwargs)
           ~~~~~~~~~~~~~~~~~~~~~~~~~~~~~~~~^^^^^^^^^^^^^^^^^
  File "C:\Users\tefba\Desktop\OverBrand\acadflow\acadflow_env\Lib\site-packages\django\utils\decorators.py", line 192, in _view_wrapper
    result = _process_exception(request, e)
  File "C:\Users\tefba\Desktop\OverBrand\acadflow\acadflow_env\Lib\site-packages\django\utils\decorators.py", line 190, in _view_wrapper
    response = view_func(request, *args, **kwargs)
  File "C:\Users\tefba\Desktop\OverBrand\acadflow\acadflow_env\Lib\site-packages\django\views\decorators\cache.py", line 80, in _view_wrapper
    response = view_func(request, *args, **kwargs)
  File "C:\Users\tefba\Desktop\OverBrand\acadflow\acadflow_env\Lib\site-packages\django\contrib\admin\sites.py", line 234, in inner
    if not self.has_permission(request):
           ~~~~~~~~~~~~~~~~~~~^^^^^^^^^
  File "C:\Users\tefba\Desktop\OverBrand\acadflow\acadflow_env\Lib\site-packages\django\contrib\admin\sites.py", line 207, in has_permission
    return request.user.is_active and request.user.is_staff
           ^^^^^^^^^^^^^^^^^^^^^^
  File "C:\Users\tefba\Desktop\OverBrand\acadflow\acadflow_env\Lib\site-packages\django\utils\functional.py", line 251, in inner
    self._setup()
    ~~~~~~~~~~~^^
  File "C:\Users\tefba\Desktop\OverBrand\acadflow\acadflow_env\Lib\site-packages\django\utils\functional.py", line 404, in _setup
    self._wrapped = self._setupfunc()
                    ~~~~~~~~~~~~~~~^^
  File "C:\Users\tefba\Desktop\OverBrand\acadflow\acadflow_env\Lib\site-packages\django\contrib\auth\middleware.py", line 39, in <lambda>
    request.user = SimpleLazyObject(lambda: get_user(request))
                                            ~~~~~~~~^^^^^^^^^
  File "C:\Users\tefba\Desktop\OverBrand\acadflow\acadflow_env\Lib\site-packages\django\contrib\auth\middleware.py", line 19, in get_user
    request._cached_user = auth.get_user(request)
                           ~~~~~~~~~~~~~^^^^^^^^^
  File "C:\Users\tefba\Desktop\OverBrand\acadflow\acadflow_env\Lib\site-packages\django\contrib\auth\__init__.py", line 311, in get_user
    user = backend.get_user(user_id)
  File "C:\Users\tefba\Desktop\OverBrand\acadflow\acadflow_env\Lib\site-packages\django\contrib\auth\backends.py", line 232, in get_user
    user = UserModel._default_manager.get(pk=user_id)
  File "C:\Users\tefba\Desktop\OverBrand\acadflow\acadflow_env\Lib\site-packages\django\db\models\manager.py", line 87, in manager_method
    return getattr(self.get_queryset(), name)(*args, **kwargs)
           ~~~~~~~~~~~~~~~~~~~~~~~~~~~~~~~~~~^^^^^^^^^^^^^^^^^
  File "C:\Users\tefba\Desktop\OverBrand\acadflow\acadflow_env\Lib\site-packages\django\db\models\query.py", line 629, in get
    num = len(clone)
  File "C:\Users\tefba\Desktop\OverBrand\acadflow\acadflow_env\Lib\site-packages\django\db\models\query.py", line 366, in __len__
    self._fetch_all()
    ~~~~~~~~~~~~~~~^^
  File "C:\Users\tefba\Desktop\OverBrand\acadflow\acadflow_env\Lib\site-packages\django\db\models\query.py", line 1945, in _fetch_all
    self._result_cache = list(self._iterable_class(self))
                         ~~~~^^^^^^^^^^^^^^^^^^^^^^^^^^^^
  File "C:\Users\tefba\Desktop\OverBrand\acadflow\acadflow_env\Lib\site-packages\django\db\models\query.py", line 91, in __iter__
    results = compiler.execute_sql(
        chunked_fetch=self.chunked_fetch, chunk_size=self.chunk_size
    )
  File "C:\Users\tefba\Desktop\OverBrand\acadflow\acadflow_env\Lib\site-packages\django\db\models\sql\compiler.py", line 1623, in execute_sql
    cursor.execute(sql, params)
    ~~~~~~~~~~~~~~^^^^^^^^^^^^^
  File "C:\Users\tefba\Desktop\OverBrand\acadflow\acadflow_env\Lib\site-packages\django\db\backends\utils.py", line 122, in execute
    return super().execute(sql, params)
           ~~~~~~~~~~~~~~~^^^^^^^^^^^^^
  File "C:\Users\tefba\Desktop\OverBrand\acadflow\acadflow_env\Lib\site-packages\django\db\backends\utils.py", line 79, in execute
    return self._execute_with_wrappers(
           ~~~~~~~~~~~~~~~~~~~~~~~~~~~^
        sql, params, many=False, executor=self._execute
        ^^^^^^^^^^^^^^^^^^^^^^^^^^^^^^^^^^^^^^^^^^^^^^^
    )
    ^
  File "C:\Users\tefba\Desktop\OverBrand\acadflow\acadflow_env\Lib\site-packages\django\db\backends\utils.py", line 92, in _execute_with_wrappers
    return executor(sql, params, many, context)
  File "C:\Users\tefba\Desktop\OverBrand\acadflow\acadflow_env\Lib\site-packages\django\db\backends\utils.py", line 100, in _execute
    with self.db.wrap_database_errors:
         ^^^^^^^^^^^^^^^^^^^^^^^^^^^^
  File "C:\Users\tefba\Desktop\OverBrand\acadflow\acadflow_env\Lib\site-packages\django\db\utils.py", line 91, in __exit__
    raise dj_exc_value.with_traceback(traceback) from exc_value
  File "C:\Users\tefba\Desktop\OverBrand\acadflow\acadflow_env\Lib\site-packages\django\db\backends\utils.py", line 105, in _execute
    return self.cursor.execute(sql, params)
           ~~~~~~~~~~~~~~~~~~~^^^^^^^^^^^^^
django.db.utils.ProgrammingError: ERREUR:  la relation « users » n'existe pas
LINE 1: ...naissance", "users"."photo", "users"."actif" FROM "users" WH...
                                                             ^

ERROR 2025-06-02 08:06:36,917 basehttp 10664 19400 "GET /admin/core/niveau/add/ HTTP/1.1" 500 193243
ERROR 2025-06-02 08:06:37,525 log 10664 19400 Internal Server Error: /admin/core/niveau/
Traceback (most recent call last):
  File "C:\Users\tefba\Desktop\OverBrand\acadflow\acadflow_env\Lib\site-packages\django\db\backends\utils.py", line 105, in _execute
    return self.cursor.execute(sql, params)
           ~~~~~~~~~~~~~~~~~~~^^^^^^^^^^^^^
psycopg2.errors.UndefinedTable: ERREUR:  la relation « users » n'existe pas
LINE 1: ...naissance", "users"."photo", "users"."actif" FROM "users" WH...
                                                             ^


The above exception was the direct cause of the following exception:

Traceback (most recent call last):
  File "C:\Users\tefba\Desktop\OverBrand\acadflow\acadflow_env\Lib\site-packages\django\core\handlers\exception.py", line 55, in inner
    response = get_response(request)
  File "C:\Users\tefba\Desktop\OverBrand\acadflow\acadflow_env\Lib\site-packages\django\core\handlers\base.py", line 197, in _get_response
    response = wrapped_callback(request, *callback_args, **callback_kwargs)
  File "C:\Users\tefba\Desktop\OverBrand\acadflow\acadflow_env\Lib\site-packages\django\contrib\admin\options.py", line 719, in wrapper
    return self.admin_site.admin_view(view)(*args, **kwargs)
           ~~~~~~~~~~~~~~~~~~~~~~~~~~~~~~~~^^^^^^^^^^^^^^^^^
  File "C:\Users\tefba\Desktop\OverBrand\acadflow\acadflow_env\Lib\site-packages\django\utils\decorators.py", line 192, in _view_wrapper
    result = _process_exception(request, e)
  File "C:\Users\tefba\Desktop\OverBrand\acadflow\acadflow_env\Lib\site-packages\django\utils\decorators.py", line 190, in _view_wrapper
    response = view_func(request, *args, **kwargs)
  File "C:\Users\tefba\Desktop\OverBrand\acadflow\acadflow_env\Lib\site-packages\django\views\decorators\cache.py", line 80, in _view_wrapper
    response = view_func(request, *args, **kwargs)
  File "C:\Users\tefba\Desktop\OverBrand\acadflow\acadflow_env\Lib\site-packages\django\contrib\admin\sites.py", line 234, in inner
    if not self.has_permission(request):
           ~~~~~~~~~~~~~~~~~~~^^^^^^^^^
  File "C:\Users\tefba\Desktop\OverBrand\acadflow\acadflow_env\Lib\site-packages\django\contrib\admin\sites.py", line 207, in has_permission
    return request.user.is_active and request.user.is_staff
           ^^^^^^^^^^^^^^^^^^^^^^
  File "C:\Users\tefba\Desktop\OverBrand\acadflow\acadflow_env\Lib\site-packages\django\utils\functional.py", line 251, in inner
    self._setup()
    ~~~~~~~~~~~^^
  File "C:\Users\tefba\Desktop\OverBrand\acadflow\acadflow_env\Lib\site-packages\django\utils\functional.py", line 404, in _setup
    self._wrapped = self._setupfunc()
                    ~~~~~~~~~~~~~~~^^
  File "C:\Users\tefba\Desktop\OverBrand\acadflow\acadflow_env\Lib\site-packages\django\contrib\auth\middleware.py", line 39, in <lambda>
    request.user = SimpleLazyObject(lambda: get_user(request))
                                            ~~~~~~~~^^^^^^^^^
  File "C:\Users\tefba\Desktop\OverBrand\acadflow\acadflow_env\Lib\site-packages\django\contrib\auth\middleware.py", line 19, in get_user
    request._cached_user = auth.get_user(request)
                           ~~~~~~~~~~~~~^^^^^^^^^
  File "C:\Users\tefba\Desktop\OverBrand\acadflow\acadflow_env\Lib\site-packages\django\contrib\auth\__init__.py", line 311, in get_user
    user = backend.get_user(user_id)
  File "C:\Users\tefba\Desktop\OverBrand\acadflow\acadflow_env\Lib\site-packages\django\contrib\auth\backends.py", line 232, in get_user
    user = UserModel._default_manager.get(pk=user_id)
  File "C:\Users\tefba\Desktop\OverBrand\acadflow\acadflow_env\Lib\site-packages\django\db\models\manager.py", line 87, in manager_method
    return getattr(self.get_queryset(), name)(*args, **kwargs)
           ~~~~~~~~~~~~~~~~~~~~~~~~~~~~~~~~~~^^^^^^^^^^^^^^^^^
  File "C:\Users\tefba\Desktop\OverBrand\acadflow\acadflow_env\Lib\site-packages\django\db\models\query.py", line 629, in get
    num = len(clone)
  File "C:\Users\tefba\Desktop\OverBrand\acadflow\acadflow_env\Lib\site-packages\django\db\models\query.py", line 366, in __len__
    self._fetch_all()
    ~~~~~~~~~~~~~~~^^
  File "C:\Users\tefba\Desktop\OverBrand\acadflow\acadflow_env\Lib\site-packages\django\db\models\query.py", line 1945, in _fetch_all
    self._result_cache = list(self._iterable_class(self))
                         ~~~~^^^^^^^^^^^^^^^^^^^^^^^^^^^^
  File "C:\Users\tefba\Desktop\OverBrand\acadflow\acadflow_env\Lib\site-packages\django\db\models\query.py", line 91, in __iter__
    results = compiler.execute_sql(
        chunked_fetch=self.chunked_fetch, chunk_size=self.chunk_size
    )
  File "C:\Users\tefba\Desktop\OverBrand\acadflow\acadflow_env\Lib\site-packages\django\db\models\sql\compiler.py", line 1623, in execute_sql
    cursor.execute(sql, params)
    ~~~~~~~~~~~~~~^^^^^^^^^^^^^
  File "C:\Users\tefba\Desktop\OverBrand\acadflow\acadflow_env\Lib\site-packages\django\db\backends\utils.py", line 122, in execute
    return super().execute(sql, params)
           ~~~~~~~~~~~~~~~^^^^^^^^^^^^^
  File "C:\Users\tefba\Desktop\OverBrand\acadflow\acadflow_env\Lib\site-packages\django\db\backends\utils.py", line 79, in execute
    return self._execute_with_wrappers(
           ~~~~~~~~~~~~~~~~~~~~~~~~~~~^
        sql, params, many=False, executor=self._execute
        ^^^^^^^^^^^^^^^^^^^^^^^^^^^^^^^^^^^^^^^^^^^^^^^
    )
    ^
  File "C:\Users\tefba\Desktop\OverBrand\acadflow\acadflow_env\Lib\site-packages\django\db\backends\utils.py", line 92, in _execute_with_wrappers
    return executor(sql, params, many, context)
  File "C:\Users\tefba\Desktop\OverBrand\acadflow\acadflow_env\Lib\site-packages\django\db\backends\utils.py", line 100, in _execute
    with self.db.wrap_database_errors:
         ^^^^^^^^^^^^^^^^^^^^^^^^^^^^
  File "C:\Users\tefba\Desktop\OverBrand\acadflow\acadflow_env\Lib\site-packages\django\db\utils.py", line 91, in __exit__
    raise dj_exc_value.with_traceback(traceback) from exc_value
  File "C:\Users\tefba\Desktop\OverBrand\acadflow\acadflow_env\Lib\site-packages\django\db\backends\utils.py", line 105, in _execute
    return self.cursor.execute(sql, params)
           ~~~~~~~~~~~~~~~~~~~^^^^^^^^^^^^^
django.db.utils.ProgrammingError: ERREUR:  la relation « users » n'existe pas
LINE 1: ...naissance", "users"."photo", "users"."actif" FROM "users" WH...
                                                             ^

ERROR 2025-06-02 08:06:37,531 basehttp 10664 19400 "GET /admin/core/niveau/ HTTP/1.1" 500 193211
ERROR 2025-06-02 08:06:40,051 log 10664 19400 Internal Server Error: /admin/
Traceback (most recent call last):
  File "C:\Users\tefba\Desktop\OverBrand\acadflow\acadflow_env\Lib\site-packages\django\db\backends\utils.py", line 105, in _execute
    return self.cursor.execute(sql, params)
           ~~~~~~~~~~~~~~~~~~~^^^^^^^^^^^^^
psycopg2.errors.UndefinedTable: ERREUR:  la relation « users » n'existe pas
LINE 1: ...naissance", "users"."photo", "users"."actif" FROM "users" WH...
                                                             ^


The above exception was the direct cause of the following exception:

Traceback (most recent call last):
  File "C:\Users\tefba\Desktop\OverBrand\acadflow\acadflow_env\Lib\site-packages\django\core\handlers\exception.py", line 55, in inner
    response = get_response(request)
  File "C:\Users\tefba\Desktop\OverBrand\acadflow\acadflow_env\Lib\site-packages\django\core\handlers\base.py", line 197, in _get_response
    response = wrapped_callback(request, *callback_args, **callback_kwargs)
  File "C:\Users\tefba\Desktop\OverBrand\acadflow\acadflow_env\Lib\site-packages\django\contrib\admin\sites.py", line 265, in wrapper
    return self.admin_view(view, cacheable)(*args, **kwargs)
           ~~~~~~~~~~~~~~~~~~~~~~~~~~~~~~~~^^^^^^^^^^^^^^^^^
  File "C:\Users\tefba\Desktop\OverBrand\acadflow\acadflow_env\Lib\site-packages\django\utils\decorators.py", line 192, in _view_wrapper
    result = _process_exception(request, e)
  File "C:\Users\tefba\Desktop\OverBrand\acadflow\acadflow_env\Lib\site-packages\django\utils\decorators.py", line 190, in _view_wrapper
    response = view_func(request, *args, **kwargs)
  File "C:\Users\tefba\Desktop\OverBrand\acadflow\acadflow_env\Lib\site-packages\django\views\decorators\cache.py", line 80, in _view_wrapper
    response = view_func(request, *args, **kwargs)
  File "C:\Users\tefba\Desktop\OverBrand\acadflow\acadflow_env\Lib\site-packages\django\contrib\admin\sites.py", line 234, in inner
    if not self.has_permission(request):
           ~~~~~~~~~~~~~~~~~~~^^^^^^^^^
  File "C:\Users\tefba\Desktop\OverBrand\acadflow\acadflow_env\Lib\site-packages\django\contrib\admin\sites.py", line 207, in has_permission
    return request.user.is_active and request.user.is_staff
           ^^^^^^^^^^^^^^^^^^^^^^
  File "C:\Users\tefba\Desktop\OverBrand\acadflow\acadflow_env\Lib\site-packages\django\utils\functional.py", line 251, in inner
    self._setup()
    ~~~~~~~~~~~^^
  File "C:\Users\tefba\Desktop\OverBrand\acadflow\acadflow_env\Lib\site-packages\django\utils\functional.py", line 404, in _setup
    self._wrapped = self._setupfunc()
                    ~~~~~~~~~~~~~~~^^
  File "C:\Users\tefba\Desktop\OverBrand\acadflow\acadflow_env\Lib\site-packages\django\contrib\auth\middleware.py", line 39, in <lambda>
    request.user = SimpleLazyObject(lambda: get_user(request))
                                            ~~~~~~~~^^^^^^^^^
  File "C:\Users\tefba\Desktop\OverBrand\acadflow\acadflow_env\Lib\site-packages\django\contrib\auth\middleware.py", line 19, in get_user
    request._cached_user = auth.get_user(request)
                           ~~~~~~~~~~~~~^^^^^^^^^
  File "C:\Users\tefba\Desktop\OverBrand\acadflow\acadflow_env\Lib\site-packages\django\contrib\auth\__init__.py", line 311, in get_user
    user = backend.get_user(user_id)
  File "C:\Users\tefba\Desktop\OverBrand\acadflow\acadflow_env\Lib\site-packages\django\contrib\auth\backends.py", line 232, in get_user
    user = UserModel._default_manager.get(pk=user_id)
  File "C:\Users\tefba\Desktop\OverBrand\acadflow\acadflow_env\Lib\site-packages\django\db\models\manager.py", line 87, in manager_method
    return getattr(self.get_queryset(), name)(*args, **kwargs)
           ~~~~~~~~~~~~~~~~~~~~~~~~~~~~~~~~~~^^^^^^^^^^^^^^^^^
  File "C:\Users\tefba\Desktop\OverBrand\acadflow\acadflow_env\Lib\site-packages\django\db\models\query.py", line 629, in get
    num = len(clone)
  File "C:\Users\tefba\Desktop\OverBrand\acadflow\acadflow_env\Lib\site-packages\django\db\models\query.py", line 366, in __len__
    self._fetch_all()
    ~~~~~~~~~~~~~~~^^
  File "C:\Users\tefba\Desktop\OverBrand\acadflow\acadflow_env\Lib\site-packages\django\db\models\query.py", line 1945, in _fetch_all
    self._result_cache = list(self._iterable_class(self))
                         ~~~~^^^^^^^^^^^^^^^^^^^^^^^^^^^^
  File "C:\Users\tefba\Desktop\OverBrand\acadflow\acadflow_env\Lib\site-packages\django\db\models\query.py", line 91, in __iter__
    results = compiler.execute_sql(
        chunked_fetch=self.chunked_fetch, chunk_size=self.chunk_size
    )
  File "C:\Users\tefba\Desktop\OverBrand\acadflow\acadflow_env\Lib\site-packages\django\db\models\sql\compiler.py", line 1623, in execute_sql
    cursor.execute(sql, params)
    ~~~~~~~~~~~~~~^^^^^^^^^^^^^
  File "C:\Users\tefba\Desktop\OverBrand\acadflow\acadflow_env\Lib\site-packages\django\db\backends\utils.py", line 122, in execute
    return super().execute(sql, params)
           ~~~~~~~~~~~~~~~^^^^^^^^^^^^^
  File "C:\Users\tefba\Desktop\OverBrand\acadflow\acadflow_env\Lib\site-packages\django\db\backends\utils.py", line 79, in execute
    return self._execute_with_wrappers(
           ~~~~~~~~~~~~~~~~~~~~~~~~~~~^
        sql, params, many=False, executor=self._execute
        ^^^^^^^^^^^^^^^^^^^^^^^^^^^^^^^^^^^^^^^^^^^^^^^
    )
    ^
  File "C:\Users\tefba\Desktop\OverBrand\acadflow\acadflow_env\Lib\site-packages\django\db\backends\utils.py", line 92, in _execute_with_wrappers
    return executor(sql, params, many, context)
  File "C:\Users\tefba\Desktop\OverBrand\acadflow\acadflow_env\Lib\site-packages\django\db\backends\utils.py", line 100, in _execute
    with self.db.wrap_database_errors:
         ^^^^^^^^^^^^^^^^^^^^^^^^^^^^
  File "C:\Users\tefba\Desktop\OverBrand\acadflow\acadflow_env\Lib\site-packages\django\db\utils.py", line 91, in __exit__
    raise dj_exc_value.with_traceback(traceback) from exc_value
  File "C:\Users\tefba\Desktop\OverBrand\acadflow\acadflow_env\Lib\site-packages\django\db\backends\utils.py", line 105, in _execute
    return self.cursor.execute(sql, params)
           ~~~~~~~~~~~~~~~~~~~^^^^^^^^^^^^^
django.db.utils.ProgrammingError: ERREUR:  la relation « users » n'existe pas
LINE 1: ...naissance", "users"."photo", "users"."actif" FROM "users" WH...
                                                             ^

ERROR 2025-06-02 08:06:40,055 basehttp 10664 19400 "GET /admin/ HTTP/1.1" 500 193219
ERROR 2025-06-02 08:15:03,509 log 17880 12588 Internal Server Error: /admin/login/
Traceback (most recent call last):
  File "C:\Users\tefba\Desktop\OverBrand\acadflow\acadflow_env\Lib\site-packages\django\db\backends\utils.py", line 105, in _execute
    return self.cursor.execute(sql, params)
           ~~~~~~~~~~~~~~~~~~~^^^^^^^^^^^^^
  File "C:\Users\tefba\Desktop\OverBrand\acadflow\acadflow_env\Lib\site-packages\django\db\backends\sqlite3\base.py", line 360, in execute
    return super().execute(query, params)
           ~~~~~~~~~~~~~~~^^^^^^^^^^^^^^^
sqlite3.OperationalError: no such table: users

The above exception was the direct cause of the following exception:

Traceback (most recent call last):
  File "C:\Users\tefba\Desktop\OverBrand\acadflow\acadflow_env\Lib\site-packages\django\core\handlers\exception.py", line 55, in inner
    response = get_response(request)
  File "C:\Users\tefba\Desktop\OverBrand\acadflow\acadflow_env\Lib\site-packages\django\core\handlers\base.py", line 197, in _get_response
    response = wrapped_callback(request, *callback_args, **callback_kwargs)
  File "C:\Users\tefba\Desktop\OverBrand\acadflow\acadflow_env\Lib\site-packages\django\utils\decorators.py", line 48, in _wrapper
    return bound_method(*args, **kwargs)
  File "C:\Users\tefba\Desktop\OverBrand\acadflow\acadflow_env\Lib\site-packages\django\views\decorators\cache.py", line 80, in _view_wrapper
    response = view_func(request, *args, **kwargs)
  File "C:\Users\tefba\Desktop\OverBrand\acadflow\acadflow_env\Lib\site-packages\django\contrib\admin\sites.py", line 449, in login
    return LoginView.as_view(**defaults)(request)
           ~~~~~~~~~~~~~~~~~~~~~~~~~~~~~^^^^^^^^^
  File "C:\Users\tefba\Desktop\OverBrand\acadflow\acadflow_env\Lib\site-packages\django\views\generic\base.py", line 104, in view
    return self.dispatch(request, *args, **kwargs)
           ~~~~~~~~~~~~~^^^^^^^^^^^^^^^^^^^^^^^^^^
  File "C:\Users\tefba\Desktop\OverBrand\acadflow\acadflow_env\Lib\site-packages\django\utils\decorators.py", line 48, in _wrapper
    return bound_method(*args, **kwargs)
  File "C:\Users\tefba\Desktop\OverBrand\acadflow\acadflow_env\Lib\site-packages\django\utils\decorators.py", line 48, in _wrapper
    return bound_method(*args, **kwargs)
  File "C:\Users\tefba\Desktop\OverBrand\acadflow\acadflow_env\Lib\site-packages\django\views\decorators\debug.py", line 143, in sensitive_post_parameters_wrapper
    return view(request, *args, **kwargs)
  File "C:\Users\tefba\Desktop\OverBrand\acadflow\acadflow_env\Lib\site-packages\django\utils\decorators.py", line 48, in _wrapper
    return bound_method(*args, **kwargs)
  File "C:\Users\tefba\Desktop\OverBrand\acadflow\acadflow_env\Lib\site-packages\django\utils\decorators.py", line 192, in _view_wrapper
    result = _process_exception(request, e)
  File "C:\Users\tefba\Desktop\OverBrand\acadflow\acadflow_env\Lib\site-packages\django\utils\decorators.py", line 190, in _view_wrapper
    response = view_func(request, *args, **kwargs)
  File "C:\Users\tefba\Desktop\OverBrand\acadflow\acadflow_env\Lib\site-packages\django\utils\decorators.py", line 48, in _wrapper
    return bound_method(*args, **kwargs)
  File "C:\Users\tefba\Desktop\OverBrand\acadflow\acadflow_env\Lib\site-packages\django\views\decorators\cache.py", line 80, in _view_wrapper
    response = view_func(request, *args, **kwargs)
  File "C:\Users\tefba\Desktop\OverBrand\acadflow\acadflow_env\Lib\site-packages\django\contrib\auth\views.py", line 89, in dispatch
    return super().dispatch(request, *args, **kwargs)
           ~~~~~~~~~~~~~~~~^^^^^^^^^^^^^^^^^^^^^^^^^^
  File "C:\Users\tefba\Desktop\OverBrand\acadflow\acadflow_env\Lib\site-packages\django\views\generic\base.py", line 143, in dispatch
    return handler(request, *args, **kwargs)
  File "C:\Users\tefba\Desktop\OverBrand\acadflow\acadflow_env\Lib\site-packages\django\views\generic\edit.py", line 150, in post
    if form.is_valid():
       ~~~~~~~~~~~~~^^
  File "C:\Users\tefba\Desktop\OverBrand\acadflow\acadflow_env\Lib\site-packages\django\forms\forms.py", line 206, in is_valid
    return self.is_bound and not self.errors
                                 ^^^^^^^^^^^
  File "C:\Users\tefba\Desktop\OverBrand\acadflow\acadflow_env\Lib\site-packages\django\forms\forms.py", line 201, in errors
    self.full_clean()
    ~~~~~~~~~~~~~~~^^
  File "C:\Users\tefba\Desktop\OverBrand\acadflow\acadflow_env\Lib\site-packages\django\forms\forms.py", line 338, in full_clean
    self._clean_form()
    ~~~~~~~~~~~~~~~~^^
  File "C:\Users\tefba\Desktop\OverBrand\acadflow\acadflow_env\Lib\site-packages\django\forms\forms.py", line 354, in _clean_form
    cleaned_data = self.clean()
  File "C:\Users\tefba\Desktop\OverBrand\acadflow\acadflow_env\Lib\site-packages\django\views\decorators\debug.py", line 75, in sensitive_variables_wrapper
    return func(*func_args, **func_kwargs)
  File "C:\Users\tefba\Desktop\OverBrand\acadflow\acadflow_env\Lib\site-packages\django\contrib\auth\forms.py", line 366, in clean
    self.user_cache = authenticate(
                      ~~~~~~~~~~~~^
        self.request, username=username, password=password
        ^^^^^^^^^^^^^^^^^^^^^^^^^^^^^^^^^^^^^^^^^^^^^^^^^^
    )
    ^
  File "C:\Users\tefba\Desktop\OverBrand\acadflow\acadflow_env\Lib\site-packages\django\views\decorators\debug.py", line 75, in sensitive_variables_wrapper
    return func(*func_args, **func_kwargs)
  File "C:\Users\tefba\Desktop\OverBrand\acadflow\acadflow_env\Lib\site-packages\django\contrib\auth\__init__.py", line 114, in authenticate
    user = backend.authenticate(request, **credentials)
  File "C:\Users\tefba\Desktop\OverBrand\acadflow\acadflow_env\Lib\site-packages\django\contrib\auth\backends.py", line 65, in authenticate
    user = UserModel._default_manager.get_by_natural_key(username)
  File "C:\Users\tefba\Desktop\OverBrand\acadflow\acadflow_env\Lib\site-packages\django\contrib\auth\base_user.py", line 37, in get_by_natural_key
    return self.get(**{self.model.USERNAME_FIELD: username})
           ~~~~~~~~^^^^^^^^^^^^^^^^^^^^^^^^^^^^^^^^^^^^^^^^^
  File "C:\Users\tefba\Desktop\OverBrand\acadflow\acadflow_env\Lib\site-packages\django\db\models\manager.py", line 87, in manager_method
    return getattr(self.get_queryset(), name)(*args, **kwargs)
           ~~~~~~~~~~~~~~~~~~~~~~~~~~~~~~~~~~^^^^^^^^^^^^^^^^^
  File "C:\Users\tefba\Desktop\OverBrand\acadflow\acadflow_env\Lib\site-packages\django\db\models\query.py", line 629, in get
    num = len(clone)
  File "C:\Users\tefba\Desktop\OverBrand\acadflow\acadflow_env\Lib\site-packages\django\db\models\query.py", line 366, in __len__
    self._fetch_all()
    ~~~~~~~~~~~~~~~^^
  File "C:\Users\tefba\Desktop\OverBrand\acadflow\acadflow_env\Lib\site-packages\django\db\models\query.py", line 1945, in _fetch_all
    self._result_cache = list(self._iterable_class(self))
                         ~~~~^^^^^^^^^^^^^^^^^^^^^^^^^^^^
  File "C:\Users\tefba\Desktop\OverBrand\acadflow\acadflow_env\Lib\site-packages\django\db\models\query.py", line 91, in __iter__
    results = compiler.execute_sql(
        chunked_fetch=self.chunked_fetch, chunk_size=self.chunk_size
    )
  File "C:\Users\tefba\Desktop\OverBrand\acadflow\acadflow_env\Lib\site-packages\django\db\models\sql\compiler.py", line 1623, in execute_sql
    cursor.execute(sql, params)
    ~~~~~~~~~~~~~~^^^^^^^^^^^^^
  File "C:\Users\tefba\Desktop\OverBrand\acadflow\acadflow_env\Lib\site-packages\django\db\backends\utils.py", line 122, in execute
    return super().execute(sql, params)
           ~~~~~~~~~~~~~~~^^^^^^^^^^^^^
  File "C:\Users\tefba\Desktop\OverBrand\acadflow\acadflow_env\Lib\site-packages\django\db\backends\utils.py", line 79, in execute
    return self._execute_with_wrappers(
           ~~~~~~~~~~~~~~~~~~~~~~~~~~~^
        sql, params, many=False, executor=self._execute
        ^^^^^^^^^^^^^^^^^^^^^^^^^^^^^^^^^^^^^^^^^^^^^^^
    )
    ^
  File "C:\Users\tefba\Desktop\OverBrand\acadflow\acadflow_env\Lib\site-packages\django\db\backends\utils.py", line 92, in _execute_with_wrappers
    return executor(sql, params, many, context)
  File "C:\Users\tefba\Desktop\OverBrand\acadflow\acadflow_env\Lib\site-packages\django\db\backends\utils.py", line 100, in _execute
    with self.db.wrap_database_errors:
         ^^^^^^^^^^^^^^^^^^^^^^^^^^^^
  File "C:\Users\tefba\Desktop\OverBrand\acadflow\acadflow_env\Lib\site-packages\django\db\utils.py", line 91, in __exit__
    raise dj_exc_value.with_traceback(traceback) from exc_value
  File "C:\Users\tefba\Desktop\OverBrand\acadflow\acadflow_env\Lib\site-packages\django\db\backends\utils.py", line 105, in _execute
    return self.cursor.execute(sql, params)
           ~~~~~~~~~~~~~~~~~~~^^^^^^^^^^^^^
  File "C:\Users\tefba\Desktop\OverBrand\acadflow\acadflow_env\Lib\site-packages\django\db\backends\sqlite3\base.py", line 360, in execute
    return super().execute(query, params)
           ~~~~~~~~~~~~~~~^^^^^^^^^^^^^^^
django.db.utils.OperationalError: no such table: users
ERROR 2025-06-02 08:15:03,546 basehttp 17880 12588 "POST /admin/login/?next=/admin/ HTTP/1.1" 500 265147
ERROR 2025-06-07 09:36:39,667 log 37916 66452 Internal Server Error: /api/auth/login/
Traceback (most recent call last):
  File "C:\Users\tefba\Desktop\OverBrand\acadflow\acadflow_env\Lib\site-packages\django\db\backends\utils.py", line 105, in _execute
    return self.cursor.execute(sql, params)
           ~~~~~~~~~~~~~~~~~~~^^^^^^^^^^^^^
  File "C:\Users\tefba\Desktop\OverBrand\acadflow\acadflow_env\Lib\site-packages\django\db\backends\sqlite3\base.py", line 360, in execute
    return super().execute(query, params)
           ~~~~~~~~~~~~~~~^^^^^^^^^^^^^^^
sqlite3.OperationalError: no such table: users

The above exception was the direct cause of the following exception:

Traceback (most recent call last):
  File "C:\Users\tefba\Desktop\OverBrand\acadflow\acadflow_env\Lib\site-packages\django\core\handlers\exception.py", line 55, in inner
    response = get_response(request)
  File "C:\Users\tefba\Desktop\OverBrand\acadflow\acadflow_env\Lib\site-packages\django\core\handlers\base.py", line 197, in _get_response
    response = wrapped_callback(request, *callback_args, **callback_kwargs)
  File "C:\Users\tefba\Desktop\OverBrand\acadflow\acadflow_env\Lib\site-packages\django\views\decorators\csrf.py", line 65, in _view_wrapper
    return view_func(request, *args, **kwargs)
  File "C:\Users\tefba\Desktop\OverBrand\acadflow\acadflow_env\Lib\site-packages\django\views\generic\base.py", line 104, in view
    return self.dispatch(request, *args, **kwargs)
           ~~~~~~~~~~~~~^^^^^^^^^^^^^^^^^^^^^^^^^^
  File "C:\Users\tefba\Desktop\OverBrand\acadflow\acadflow_env\Lib\site-packages\rest_framework\views.py", line 515, in dispatch
    response = self.handle_exception(exc)
  File "C:\Users\tefba\Desktop\OverBrand\acadflow\acadflow_env\Lib\site-packages\rest_framework\views.py", line 475, in handle_exception
    self.raise_uncaught_exception(exc)
    ~~~~~~~~~~~~~~~~~~~~~~~~~~~~~^^^^^
  File "C:\Users\tefba\Desktop\OverBrand\acadflow\acadflow_env\Lib\site-packages\rest_framework\views.py", line 486, in raise_uncaught_exception
    raise exc
  File "C:\Users\tefba\Desktop\OverBrand\acadflow\acadflow_env\Lib\site-packages\rest_framework\views.py", line 512, in dispatch
    response = handler(request, *args, **kwargs)
  File "C:\Users\tefba\Desktop\OverBrand\acadflow\acadflow_env\Lib\site-packages\rest_framework\decorators.py", line 50, in handler
    return func(*args, **kwargs)
  File "C:\Users\tefba\Desktop\OverBrand\acadflow\acadflow_backend\users\views.py", line 24, in login_view
    if serializer.is_valid():
       ~~~~~~~~~~~~~~~~~~~^^
  File "C:\Users\tefba\Desktop\OverBrand\acadflow\acadflow_env\Lib\site-packages\rest_framework\serializers.py", line 225, in is_valid
    self._validated_data = self.run_validation(self.initial_data)
                           ~~~~~~~~~~~~~~~~~~~^^^^^^^^^^^^^^^^^^^
  File "C:\Users\tefba\Desktop\OverBrand\acadflow\acadflow_env\Lib\site-packages\rest_framework\serializers.py", line 447, in run_validation
    value = self.validate(value)
  File "C:\Users\tefba\Desktop\OverBrand\acadflow\acadflow_backend\users\serializers.py", line 73, in validate
    user = authenticate(username=username, password=password)
  File "C:\Users\tefba\Desktop\OverBrand\acadflow\acadflow_env\Lib\site-packages\django\views\decorators\debug.py", line 75, in sensitive_variables_wrapper
    return func(*func_args, **func_kwargs)
  File "C:\Users\tefba\Desktop\OverBrand\acadflow\acadflow_env\Lib\site-packages\django\contrib\auth\__init__.py", line 114, in authenticate
    user = backend.authenticate(request, **credentials)
  File "C:\Users\tefba\Desktop\OverBrand\acadflow\acadflow_env\Lib\site-packages\django\contrib\auth\backends.py", line 65, in authenticate
    user = UserModel._default_manager.get_by_natural_key(username)
  File "C:\Users\tefba\Desktop\OverBrand\acadflow\acadflow_env\Lib\site-packages\django\contrib\auth\base_user.py", line 37, in get_by_natural_key
    return self.get(**{self.model.USERNAME_FIELD: username})
           ~~~~~~~~^^^^^^^^^^^^^^^^^^^^^^^^^^^^^^^^^^^^^^^^^
  File "C:\Users\tefba\Desktop\OverBrand\acadflow\acadflow_env\Lib\site-packages\django\db\models\manager.py", line 87, in manager_method
    return getattr(self.get_queryset(), name)(*args, **kwargs)
           ~~~~~~~~~~~~~~~~~~~~~~~~~~~~~~~~~~^^^^^^^^^^^^^^^^^
  File "C:\Users\tefba\Desktop\OverBrand\acadflow\acadflow_env\Lib\site-packages\django\db\models\query.py", line 629, in get
    num = len(clone)
  File "C:\Users\tefba\Desktop\OverBrand\acadflow\acadflow_env\Lib\site-packages\django\db\models\query.py", line 366, in __len__
    self._fetch_all()
    ~~~~~~~~~~~~~~~^^
  File "C:\Users\tefba\Desktop\OverBrand\acadflow\acadflow_env\Lib\site-packages\django\db\models\query.py", line 1945, in _fetch_all
    self._result_cache = list(self._iterable_class(self))
                         ~~~~^^^^^^^^^^^^^^^^^^^^^^^^^^^^
  File "C:\Users\tefba\Desktop\OverBrand\acadflow\acadflow_env\Lib\site-packages\django\db\models\query.py", line 91, in __iter__
    results = compiler.execute_sql(
        chunked_fetch=self.chunked_fetch, chunk_size=self.chunk_size
    )
  File "C:\Users\tefba\Desktop\OverBrand\acadflow\acadflow_env\Lib\site-packages\django\db\models\sql\compiler.py", line 1623, in execute_sql
    cursor.execute(sql, params)
    ~~~~~~~~~~~~~~^^^^^^^^^^^^^
  File "C:\Users\tefba\Desktop\OverBrand\acadflow\acadflow_env\Lib\site-packages\django\db\backends\utils.py", line 122, in execute
    return super().execute(sql, params)
           ~~~~~~~~~~~~~~~^^^^^^^^^^^^^
  File "C:\Users\tefba\Desktop\OverBrand\acadflow\acadflow_env\Lib\site-packages\django\db\backends\utils.py", line 79, in execute
    return self._execute_with_wrappers(
           ~~~~~~~~~~~~~~~~~~~~~~~~~~~^
        sql, params, many=False, executor=self._execute
        ^^^^^^^^^^^^^^^^^^^^^^^^^^^^^^^^^^^^^^^^^^^^^^^
    )
    ^
  File "C:\Users\tefba\Desktop\OverBrand\acadflow\acadflow_env\Lib\site-packages\django\db\backends\utils.py", line 92, in _execute_with_wrappers
    return executor(sql, params, many, context)
  File "C:\Users\tefba\Desktop\OverBrand\acadflow\acadflow_env\Lib\site-packages\django\db\backends\utils.py", line 100, in _execute
    with self.db.wrap_database_errors:
         ^^^^^^^^^^^^^^^^^^^^^^^^^^^^
  File "C:\Users\tefba\Desktop\OverBrand\acadflow\acadflow_env\Lib\site-packages\django\db\utils.py", line 91, in __exit__
    raise dj_exc_value.with_traceback(traceback) from exc_value
  File "C:\Users\tefba\Desktop\OverBrand\acadflow\acadflow_env\Lib\site-packages\django\db\backends\utils.py", line 105, in _execute
    return self.cursor.execute(sql, params)
           ~~~~~~~~~~~~~~~~~~~^^^^^^^^^^^^^
  File "C:\Users\tefba\Desktop\OverBrand\acadflow\acadflow_env\Lib\site-packages\django\db\backends\sqlite3\base.py", line 360, in execute
    return super().execute(query, params)
           ~~~~~~~~~~~~~~~^^^^^^^^^^^^^^^
django.db.utils.OperationalError: no such table: users
ERROR 2025-06-07 09:36:39,676 basehttp 37916 66452 "POST /api/auth/login/ HTTP/1.1" 500 213544
ERROR 2025-06-07 09:39:13,393 log 37916 66452 Internal Server Error: /api/auth/login/
Traceback (most recent call last):
  File "C:\Users\tefba\Desktop\OverBrand\acadflow\acadflow_env\Lib\site-packages\django\db\backends\utils.py", line 105, in _execute
    return self.cursor.execute(sql, params)
           ~~~~~~~~~~~~~~~~~~~^^^^^^^^^^^^^
  File "C:\Users\tefba\Desktop\OverBrand\acadflow\acadflow_env\Lib\site-packages\django\db\backends\sqlite3\base.py", line 360, in execute
    return super().execute(query, params)
           ~~~~~~~~~~~~~~~^^^^^^^^^^^^^^^
sqlite3.OperationalError: no such table: users

The above exception was the direct cause of the following exception:

Traceback (most recent call last):
  File "C:\Users\tefba\Desktop\OverBrand\acadflow\acadflow_env\Lib\site-packages\django\core\handlers\exception.py", line 55, in inner
    response = get_response(request)
  File "C:\Users\tefba\Desktop\OverBrand\acadflow\acadflow_env\Lib\site-packages\django\core\handlers\base.py", line 197, in _get_response
    response = wrapped_callback(request, *callback_args, **callback_kwargs)
  File "C:\Users\tefba\Desktop\OverBrand\acadflow\acadflow_env\Lib\site-packages\django\views\decorators\csrf.py", line 65, in _view_wrapper
    return view_func(request, *args, **kwargs)
  File "C:\Users\tefba\Desktop\OverBrand\acadflow\acadflow_env\Lib\site-packages\django\views\generic\base.py", line 104, in view
    return self.dispatch(request, *args, **kwargs)
           ~~~~~~~~~~~~~^^^^^^^^^^^^^^^^^^^^^^^^^^
  File "C:\Users\tefba\Desktop\OverBrand\acadflow\acadflow_env\Lib\site-packages\rest_framework\views.py", line 515, in dispatch
    response = self.handle_exception(exc)
  File "C:\Users\tefba\Desktop\OverBrand\acadflow\acadflow_env\Lib\site-packages\rest_framework\views.py", line 475, in handle_exception
    self.raise_uncaught_exception(exc)
    ~~~~~~~~~~~~~~~~~~~~~~~~~~~~~^^^^^
  File "C:\Users\tefba\Desktop\OverBrand\acadflow\acadflow_env\Lib\site-packages\rest_framework\views.py", line 486, in raise_uncaught_exception
    raise exc
  File "C:\Users\tefba\Desktop\OverBrand\acadflow\acadflow_env\Lib\site-packages\rest_framework\views.py", line 512, in dispatch
    response = handler(request, *args, **kwargs)
  File "C:\Users\tefba\Desktop\OverBrand\acadflow\acadflow_env\Lib\site-packages\rest_framework\decorators.py", line 50, in handler
    return func(*args, **kwargs)
  File "C:\Users\tefba\Desktop\OverBrand\acadflow\acadflow_backend\users\views.py", line 24, in login_view
    if serializer.is_valid():
       ~~~~~~~~~~~~~~~~~~~^^
  File "C:\Users\tefba\Desktop\OverBrand\acadflow\acadflow_env\Lib\site-packages\rest_framework\serializers.py", line 225, in is_valid
    self._validated_data = self.run_validation(self.initial_data)
                           ~~~~~~~~~~~~~~~~~~~^^^^^^^^^^^^^^^^^^^
  File "C:\Users\tefba\Desktop\OverBrand\acadflow\acadflow_env\Lib\site-packages\rest_framework\serializers.py", line 447, in run_validation
    value = self.validate(value)
  File "C:\Users\tefba\Desktop\OverBrand\acadflow\acadflow_backend\users\serializers.py", line 73, in validate
    user = authenticate(username=username, password=password)
  File "C:\Users\tefba\Desktop\OverBrand\acadflow\acadflow_env\Lib\site-packages\django\views\decorators\debug.py", line 75, in sensitive_variables_wrapper
    return func(*func_args, **func_kwargs)
  File "C:\Users\tefba\Desktop\OverBrand\acadflow\acadflow_env\Lib\site-packages\django\contrib\auth\__init__.py", line 114, in authenticate
    user = backend.authenticate(request, **credentials)
  File "C:\Users\tefba\Desktop\OverBrand\acadflow\acadflow_env\Lib\site-packages\django\contrib\auth\backends.py", line 65, in authenticate
    user = UserModel._default_manager.get_by_natural_key(username)
  File "C:\Users\tefba\Desktop\OverBrand\acadflow\acadflow_env\Lib\site-packages\django\contrib\auth\base_user.py", line 37, in get_by_natural_key
    return self.get(**{self.model.USERNAME_FIELD: username})
           ~~~~~~~~^^^^^^^^^^^^^^^^^^^^^^^^^^^^^^^^^^^^^^^^^
  File "C:\Users\tefba\Desktop\OverBrand\acadflow\acadflow_env\Lib\site-packages\django\db\models\manager.py", line 87, in manager_method
    return getattr(self.get_queryset(), name)(*args, **kwargs)
           ~~~~~~~~~~~~~~~~~~~~~~~~~~~~~~~~~~^^^^^^^^^^^^^^^^^
  File "C:\Users\tefba\Desktop\OverBrand\acadflow\acadflow_env\Lib\site-packages\django\db\models\query.py", line 629, in get
    num = len(clone)
  File "C:\Users\tefba\Desktop\OverBrand\acadflow\acadflow_env\Lib\site-packages\django\db\models\query.py", line 366, in __len__
    self._fetch_all()
    ~~~~~~~~~~~~~~~^^
  File "C:\Users\tefba\Desktop\OverBrand\acadflow\acadflow_env\Lib\site-packages\django\db\models\query.py", line 1945, in _fetch_all
    self._result_cache = list(self._iterable_class(self))
                         ~~~~^^^^^^^^^^^^^^^^^^^^^^^^^^^^
  File "C:\Users\tefba\Desktop\OverBrand\acadflow\acadflow_env\Lib\site-packages\django\db\models\query.py", line 91, in __iter__
    results = compiler.execute_sql(
        chunked_fetch=self.chunked_fetch, chunk_size=self.chunk_size
    )
  File "C:\Users\tefba\Desktop\OverBrand\acadflow\acadflow_env\Lib\site-packages\django\db\models\sql\compiler.py", line 1623, in execute_sql
    cursor.execute(sql, params)
    ~~~~~~~~~~~~~~^^^^^^^^^^^^^
  File "C:\Users\tefba\Desktop\OverBrand\acadflow\acadflow_env\Lib\site-packages\django\db\backends\utils.py", line 122, in execute
    return super().execute(sql, params)
           ~~~~~~~~~~~~~~~^^^^^^^^^^^^^
  File "C:\Users\tefba\Desktop\OverBrand\acadflow\acadflow_env\Lib\site-packages\django\db\backends\utils.py", line 79, in execute
    return self._execute_with_wrappers(
           ~~~~~~~~~~~~~~~~~~~~~~~~~~~^
        sql, params, many=False, executor=self._execute
        ^^^^^^^^^^^^^^^^^^^^^^^^^^^^^^^^^^^^^^^^^^^^^^^
    )
    ^
  File "C:\Users\tefba\Desktop\OverBrand\acadflow\acadflow_env\Lib\site-packages\django\db\backends\utils.py", line 92, in _execute_with_wrappers
    return executor(sql, params, many, context)
  File "C:\Users\tefba\Desktop\OverBrand\acadflow\acadflow_env\Lib\site-packages\django\db\backends\utils.py", line 100, in _execute
    with self.db.wrap_database_errors:
         ^^^^^^^^^^^^^^^^^^^^^^^^^^^^
  File "C:\Users\tefba\Desktop\OverBrand\acadflow\acadflow_env\Lib\site-packages\django\db\utils.py", line 91, in __exit__
    raise dj_exc_value.with_traceback(traceback) from exc_value
  File "C:\Users\tefba\Desktop\OverBrand\acadflow\acadflow_env\Lib\site-packages\django\db\backends\utils.py", line 105, in _execute
    return self.cursor.execute(sql, params)
           ~~~~~~~~~~~~~~~~~~~^^^^^^^^^^^^^
  File "C:\Users\tefba\Desktop\OverBrand\acadflow\acadflow_env\Lib\site-packages\django\db\backends\sqlite3\base.py", line 360, in execute
    return super().execute(query, params)
           ~~~~~~~~~~~~~~~^^^^^^^^^^^^^^^
django.db.utils.OperationalError: no such table: users
ERROR 2025-06-07 09:39:13,402 basehttp 37916 66452 "POST /api/auth/login/ HTTP/1.1" 500 213244
ERROR 2025-06-07 09:40:01,248 log 37916 66396 Internal Server Error: /api/auth/login/
Traceback (most recent call last):
  File "C:\Users\tefba\Desktop\OverBrand\acadflow\acadflow_env\Lib\site-packages\django\db\backends\utils.py", line 105, in _execute
    return self.cursor.execute(sql, params)
           ~~~~~~~~~~~~~~~~~~~^^^^^^^^^^^^^
  File "C:\Users\tefba\Desktop\OverBrand\acadflow\acadflow_env\Lib\site-packages\django\db\backends\sqlite3\base.py", line 360, in execute
    return super().execute(query, params)
           ~~~~~~~~~~~~~~~^^^^^^^^^^^^^^^
sqlite3.OperationalError: no such table: users

The above exception was the direct cause of the following exception:

Traceback (most recent call last):
  File "C:\Users\tefba\Desktop\OverBrand\acadflow\acadflow_env\Lib\site-packages\django\core\handlers\exception.py", line 55, in inner
    response = get_response(request)
  File "C:\Users\tefba\Desktop\OverBrand\acadflow\acadflow_env\Lib\site-packages\django\core\handlers\base.py", line 197, in _get_response
    response = wrapped_callback(request, *callback_args, **callback_kwargs)
  File "C:\Users\tefba\Desktop\OverBrand\acadflow\acadflow_env\Lib\site-packages\django\views\decorators\csrf.py", line 65, in _view_wrapper
    return view_func(request, *args, **kwargs)
  File "C:\Users\tefba\Desktop\OverBrand\acadflow\acadflow_env\Lib\site-packages\django\views\generic\base.py", line 104, in view
    return self.dispatch(request, *args, **kwargs)
           ~~~~~~~~~~~~~^^^^^^^^^^^^^^^^^^^^^^^^^^
  File "C:\Users\tefba\Desktop\OverBrand\acadflow\acadflow_env\Lib\site-packages\rest_framework\views.py", line 515, in dispatch
    response = self.handle_exception(exc)
  File "C:\Users\tefba\Desktop\OverBrand\acadflow\acadflow_env\Lib\site-packages\rest_framework\views.py", line 475, in handle_exception
    self.raise_uncaught_exception(exc)
    ~~~~~~~~~~~~~~~~~~~~~~~~~~~~~^^^^^
  File "C:\Users\tefba\Desktop\OverBrand\acadflow\acadflow_env\Lib\site-packages\rest_framework\views.py", line 486, in raise_uncaught_exception
    raise exc
  File "C:\Users\tefba\Desktop\OverBrand\acadflow\acadflow_env\Lib\site-packages\rest_framework\views.py", line 512, in dispatch
    response = handler(request, *args, **kwargs)
  File "C:\Users\tefba\Desktop\OverBrand\acadflow\acadflow_env\Lib\site-packages\rest_framework\decorators.py", line 50, in handler
    return func(*args, **kwargs)
  File "C:\Users\tefba\Desktop\OverBrand\acadflow\acadflow_backend\users\views.py", line 24, in login_view
    if serializer.is_valid():
       ~~~~~~~~~~~~~~~~~~~^^
  File "C:\Users\tefba\Desktop\OverBrand\acadflow\acadflow_env\Lib\site-packages\rest_framework\serializers.py", line 225, in is_valid
    self._validated_data = self.run_validation(self.initial_data)
                           ~~~~~~~~~~~~~~~~~~~^^^^^^^^^^^^^^^^^^^
  File "C:\Users\tefba\Desktop\OverBrand\acadflow\acadflow_env\Lib\site-packages\rest_framework\serializers.py", line 447, in run_validation
    value = self.validate(value)
  File "C:\Users\tefba\Desktop\OverBrand\acadflow\acadflow_backend\users\serializers.py", line 73, in validate
    user = authenticate(username=username, password=password)
  File "C:\Users\tefba\Desktop\OverBrand\acadflow\acadflow_env\Lib\site-packages\django\views\decorators\debug.py", line 75, in sensitive_variables_wrapper
    return func(*func_args, **func_kwargs)
  File "C:\Users\tefba\Desktop\OverBrand\acadflow\acadflow_env\Lib\site-packages\django\contrib\auth\__init__.py", line 114, in authenticate
    user = backend.authenticate(request, **credentials)
  File "C:\Users\tefba\Desktop\OverBrand\acadflow\acadflow_env\Lib\site-packages\django\contrib\auth\backends.py", line 65, in authenticate
    user = UserModel._default_manager.get_by_natural_key(username)
  File "C:\Users\tefba\Desktop\OverBrand\acadflow\acadflow_env\Lib\site-packages\django\contrib\auth\base_user.py", line 37, in get_by_natural_key
    return self.get(**{self.model.USERNAME_FIELD: username})
           ~~~~~~~~^^^^^^^^^^^^^^^^^^^^^^^^^^^^^^^^^^^^^^^^^
  File "C:\Users\tefba\Desktop\OverBrand\acadflow\acadflow_env\Lib\site-packages\django\db\models\manager.py", line 87, in manager_method
    return getattr(self.get_queryset(), name)(*args, **kwargs)
           ~~~~~~~~~~~~~~~~~~~~~~~~~~~~~~~~~~^^^^^^^^^^^^^^^^^
  File "C:\Users\tefba\Desktop\OverBrand\acadflow\acadflow_env\Lib\site-packages\django\db\models\query.py", line 629, in get
    num = len(clone)
  File "C:\Users\tefba\Desktop\OverBrand\acadflow\acadflow_env\Lib\site-packages\django\db\models\query.py", line 366, in __len__
    self._fetch_all()
    ~~~~~~~~~~~~~~~^^
  File "C:\Users\tefba\Desktop\OverBrand\acadflow\acadflow_env\Lib\site-packages\django\db\models\query.py", line 1945, in _fetch_all
    self._result_cache = list(self._iterable_class(self))
                         ~~~~^^^^^^^^^^^^^^^^^^^^^^^^^^^^
  File "C:\Users\tefba\Desktop\OverBrand\acadflow\acadflow_env\Lib\site-packages\django\db\models\query.py", line 91, in __iter__
    results = compiler.execute_sql(
        chunked_fetch=self.chunked_fetch, chunk_size=self.chunk_size
    )
  File "C:\Users\tefba\Desktop\OverBrand\acadflow\acadflow_env\Lib\site-packages\django\db\models\sql\compiler.py", line 1623, in execute_sql
    cursor.execute(sql, params)
    ~~~~~~~~~~~~~~^^^^^^^^^^^^^
  File "C:\Users\tefba\Desktop\OverBrand\acadflow\acadflow_env\Lib\site-packages\django\db\backends\utils.py", line 122, in execute
    return super().execute(sql, params)
           ~~~~~~~~~~~~~~~^^^^^^^^^^^^^
  File "C:\Users\tefba\Desktop\OverBrand\acadflow\acadflow_env\Lib\site-packages\django\db\backends\utils.py", line 79, in execute
    return self._execute_with_wrappers(
           ~~~~~~~~~~~~~~~~~~~~~~~~~~~^
        sql, params, many=False, executor=self._execute
        ^^^^^^^^^^^^^^^^^^^^^^^^^^^^^^^^^^^^^^^^^^^^^^^
    )
    ^
  File "C:\Users\tefba\Desktop\OverBrand\acadflow\acadflow_env\Lib\site-packages\django\db\backends\utils.py", line 92, in _execute_with_wrappers
    return executor(sql, params, many, context)
  File "C:\Users\tefba\Desktop\OverBrand\acadflow\acadflow_env\Lib\site-packages\django\db\backends\utils.py", line 100, in _execute
    with self.db.wrap_database_errors:
         ^^^^^^^^^^^^^^^^^^^^^^^^^^^^
  File "C:\Users\tefba\Desktop\OverBrand\acadflow\acadflow_env\Lib\site-packages\django\db\utils.py", line 91, in __exit__
    raise dj_exc_value.with_traceback(traceback) from exc_value
  File "C:\Users\tefba\Desktop\OverBrand\acadflow\acadflow_env\Lib\site-packages\django\db\backends\utils.py", line 105, in _execute
    return self.cursor.execute(sql, params)
           ~~~~~~~~~~~~~~~~~~~^^^^^^^^^^^^^
  File "C:\Users\tefba\Desktop\OverBrand\acadflow\acadflow_env\Lib\site-packages\django\db\backends\sqlite3\base.py", line 360, in execute
    return super().execute(query, params)
           ~~~~~~~~~~~~~~~^^^^^^^^^^^^^^^
django.db.utils.OperationalError: no such table: users
ERROR 2025-06-07 09:40:01,258 basehttp 37916 66396 "POST /api/auth/login/ HTTP/1.1" 500 213234
ERROR 2025-06-07 09:44:55,114 log 37916 25004 Internal Server Error: /api/auth/login/
Traceback (most recent call last):
  File "C:\Users\tefba\Desktop\OverBrand\acadflow\acadflow_env\Lib\site-packages\django\db\backends\utils.py", line 105, in _execute
    return self.cursor.execute(sql, params)
           ~~~~~~~~~~~~~~~~~~~^^^^^^^^^^^^^
  File "C:\Users\tefba\Desktop\OverBrand\acadflow\acadflow_env\Lib\site-packages\django\db\backends\sqlite3\base.py", line 360, in execute
    return super().execute(query, params)
           ~~~~~~~~~~~~~~~^^^^^^^^^^^^^^^
sqlite3.OperationalError: no such table: users

The above exception was the direct cause of the following exception:

Traceback (most recent call last):
  File "C:\Users\tefba\Desktop\OverBrand\acadflow\acadflow_env\Lib\site-packages\django\core\handlers\exception.py", line 55, in inner
    response = get_response(request)
  File "C:\Users\tefba\Desktop\OverBrand\acadflow\acadflow_env\Lib\site-packages\django\core\handlers\base.py", line 197, in _get_response
    response = wrapped_callback(request, *callback_args, **callback_kwargs)
  File "C:\Users\tefba\Desktop\OverBrand\acadflow\acadflow_env\Lib\site-packages\django\views\decorators\csrf.py", line 65, in _view_wrapper
    return view_func(request, *args, **kwargs)
  File "C:\Users\tefba\Desktop\OverBrand\acadflow\acadflow_env\Lib\site-packages\django\views\generic\base.py", line 104, in view
    return self.dispatch(request, *args, **kwargs)
           ~~~~~~~~~~~~~^^^^^^^^^^^^^^^^^^^^^^^^^^
  File "C:\Users\tefba\Desktop\OverBrand\acadflow\acadflow_env\Lib\site-packages\rest_framework\views.py", line 515, in dispatch
    response = self.handle_exception(exc)
  File "C:\Users\tefba\Desktop\OverBrand\acadflow\acadflow_env\Lib\site-packages\rest_framework\views.py", line 475, in handle_exception
    self.raise_uncaught_exception(exc)
    ~~~~~~~~~~~~~~~~~~~~~~~~~~~~~^^^^^
  File "C:\Users\tefba\Desktop\OverBrand\acadflow\acadflow_env\Lib\site-packages\rest_framework\views.py", line 486, in raise_uncaught_exception
    raise exc
  File "C:\Users\tefba\Desktop\OverBrand\acadflow\acadflow_env\Lib\site-packages\rest_framework\views.py", line 512, in dispatch
    response = handler(request, *args, **kwargs)
  File "C:\Users\tefba\Desktop\OverBrand\acadflow\acadflow_env\Lib\site-packages\rest_framework\decorators.py", line 50, in handler
    return func(*args, **kwargs)
  File "C:\Users\tefba\Desktop\OverBrand\acadflow\acadflow_backend\users\views.py", line 24, in login_view
    if serializer.is_valid():
       ~~~~~~~~~~~~~~~~~~~^^
  File "C:\Users\tefba\Desktop\OverBrand\acadflow\acadflow_env\Lib\site-packages\rest_framework\serializers.py", line 225, in is_valid
    self._validated_data = self.run_validation(self.initial_data)
                           ~~~~~~~~~~~~~~~~~~~^^^^^^^^^^^^^^^^^^^
  File "C:\Users\tefba\Desktop\OverBrand\acadflow\acadflow_env\Lib\site-packages\rest_framework\serializers.py", line 447, in run_validation
    value = self.validate(value)
  File "C:\Users\tefba\Desktop\OverBrand\acadflow\acadflow_backend\users\serializers.py", line 73, in validate
    user = authenticate(username=username, password=password)
  File "C:\Users\tefba\Desktop\OverBrand\acadflow\acadflow_env\Lib\site-packages\django\views\decorators\debug.py", line 75, in sensitive_variables_wrapper
    return func(*func_args, **func_kwargs)
  File "C:\Users\tefba\Desktop\OverBrand\acadflow\acadflow_env\Lib\site-packages\django\contrib\auth\__init__.py", line 114, in authenticate
    user = backend.authenticate(request, **credentials)
  File "C:\Users\tefba\Desktop\OverBrand\acadflow\acadflow_env\Lib\site-packages\django\contrib\auth\backends.py", line 65, in authenticate
    user = UserModel._default_manager.get_by_natural_key(username)
  File "C:\Users\tefba\Desktop\OverBrand\acadflow\acadflow_env\Lib\site-packages\django\contrib\auth\base_user.py", line 37, in get_by_natural_key
    return self.get(**{self.model.USERNAME_FIELD: username})
           ~~~~~~~~^^^^^^^^^^^^^^^^^^^^^^^^^^^^^^^^^^^^^^^^^
  File "C:\Users\tefba\Desktop\OverBrand\acadflow\acadflow_env\Lib\site-packages\django\db\models\manager.py", line 87, in manager_method
    return getattr(self.get_queryset(), name)(*args, **kwargs)
           ~~~~~~~~~~~~~~~~~~~~~~~~~~~~~~~~~~^^^^^^^^^^^^^^^^^
  File "C:\Users\tefba\Desktop\OverBrand\acadflow\acadflow_env\Lib\site-packages\django\db\models\query.py", line 629, in get
    num = len(clone)
  File "C:\Users\tefba\Desktop\OverBrand\acadflow\acadflow_env\Lib\site-packages\django\db\models\query.py", line 366, in __len__
    self._fetch_all()
    ~~~~~~~~~~~~~~~^^
  File "C:\Users\tefba\Desktop\OverBrand\acadflow\acadflow_env\Lib\site-packages\django\db\models\query.py", line 1945, in _fetch_all
    self._result_cache = list(self._iterable_class(self))
                         ~~~~^^^^^^^^^^^^^^^^^^^^^^^^^^^^
  File "C:\Users\tefba\Desktop\OverBrand\acadflow\acadflow_env\Lib\site-packages\django\db\models\query.py", line 91, in __iter__
    results = compiler.execute_sql(
        chunked_fetch=self.chunked_fetch, chunk_size=self.chunk_size
    )
  File "C:\Users\tefba\Desktop\OverBrand\acadflow\acadflow_env\Lib\site-packages\django\db\models\sql\compiler.py", line 1623, in execute_sql
    cursor.execute(sql, params)
    ~~~~~~~~~~~~~~^^^^^^^^^^^^^
  File "C:\Users\tefba\Desktop\OverBrand\acadflow\acadflow_env\Lib\site-packages\django\db\backends\utils.py", line 122, in execute
    return super().execute(sql, params)
           ~~~~~~~~~~~~~~~^^^^^^^^^^^^^
  File "C:\Users\tefba\Desktop\OverBrand\acadflow\acadflow_env\Lib\site-packages\django\db\backends\utils.py", line 79, in execute
    return self._execute_with_wrappers(
           ~~~~~~~~~~~~~~~~~~~~~~~~~~~^
        sql, params, many=False, executor=self._execute
        ^^^^^^^^^^^^^^^^^^^^^^^^^^^^^^^^^^^^^^^^^^^^^^^
    )
    ^
  File "C:\Users\tefba\Desktop\OverBrand\acadflow\acadflow_env\Lib\site-packages\django\db\backends\utils.py", line 92, in _execute_with_wrappers
    return executor(sql, params, many, context)
  File "C:\Users\tefba\Desktop\OverBrand\acadflow\acadflow_env\Lib\site-packages\django\db\backends\utils.py", line 100, in _execute
    with self.db.wrap_database_errors:
         ^^^^^^^^^^^^^^^^^^^^^^^^^^^^
  File "C:\Users\tefba\Desktop\OverBrand\acadflow\acadflow_env\Lib\site-packages\django\db\utils.py", line 91, in __exit__
    raise dj_exc_value.with_traceback(traceback) from exc_value
  File "C:\Users\tefba\Desktop\OverBrand\acadflow\acadflow_env\Lib\site-packages\django\db\backends\utils.py", line 105, in _execute
    return self.cursor.execute(sql, params)
           ~~~~~~~~~~~~~~~~~~~^^^^^^^^^^^^^
  File "C:\Users\tefba\Desktop\OverBrand\acadflow\acadflow_env\Lib\site-packages\django\db\backends\sqlite3\base.py", line 360, in execute
    return super().execute(query, params)
           ~~~~~~~~~~~~~~~^^^^^^^^^^^^^^^
django.db.utils.OperationalError: no such table: users
ERROR 2025-06-07 09:44:55,117 basehttp 37916 25004 "POST /api/auth/login/ HTTP/1.1" 500 213234
ERROR 2025-06-07 10:42:24,113 log 37916 61528 Internal Server Error: /api/auth/users/me/
Traceback (most recent call last):
  File "C:\Users\tefba\Desktop\OverBrand\acadflow\acadflow_env\Lib\site-packages\django\db\backends\utils.py", line 105, in _execute
    return self.cursor.execute(sql, params)
           ~~~~~~~~~~~~~~~~~~~^^^^^^^^^^^^^
  File "C:\Users\tefba\Desktop\OverBrand\acadflow\acadflow_env\Lib\site-packages\django\db\backends\sqlite3\base.py", line 360, in execute
    return super().execute(query, params)
           ~~~~~~~~~~~~~~~^^^^^^^^^^^^^^^
sqlite3.OperationalError: no such table: users

The above exception was the direct cause of the following exception:

Traceback (most recent call last):
  File "C:\Users\tefba\Desktop\OverBrand\acadflow\acadflow_env\Lib\site-packages\django\core\handlers\exception.py", line 55, in inner
    response = get_response(request)
  File "C:\Users\tefba\Desktop\OverBrand\acadflow\acadflow_env\Lib\site-packages\django\core\handlers\base.py", line 197, in _get_response
    response = wrapped_callback(request, *callback_args, **callback_kwargs)
  File "C:\Users\tefba\Desktop\OverBrand\acadflow\acadflow_env\Lib\site-packages\django\views\decorators\csrf.py", line 65, in _view_wrapper
    return view_func(request, *args, **kwargs)
  File "C:\Users\tefba\Desktop\OverBrand\acadflow\acadflow_env\Lib\site-packages\rest_framework\viewsets.py", line 125, in view
    return self.dispatch(request, *args, **kwargs)
           ~~~~~~~~~~~~~^^^^^^^^^^^^^^^^^^^^^^^^^^
  File "C:\Users\tefba\Desktop\OverBrand\acadflow\acadflow_env\Lib\site-packages\rest_framework\views.py", line 515, in dispatch
    response = self.handle_exception(exc)
  File "C:\Users\tefba\Desktop\OverBrand\acadflow\acadflow_env\Lib\site-packages\rest_framework\views.py", line 475, in handle_exception
    self.raise_uncaught_exception(exc)
    ~~~~~~~~~~~~~~~~~~~~~~~~~~~~~^^^^^
  File "C:\Users\tefba\Desktop\OverBrand\acadflow\acadflow_env\Lib\site-packages\rest_framework\views.py", line 486, in raise_uncaught_exception
    raise exc
  File "C:\Users\tefba\Desktop\OverBrand\acadflow\acadflow_env\Lib\site-packages\rest_framework\views.py", line 503, in dispatch
    self.initial(request, *args, **kwargs)
    ~~~~~~~~~~~~^^^^^^^^^^^^^^^^^^^^^^^^^^
  File "C:\Users\tefba\Desktop\OverBrand\acadflow\acadflow_env\Lib\site-packages\rest_framework\views.py", line 420, in initial
    self.perform_authentication(request)
    ~~~~~~~~~~~~~~~~~~~~~~~~~~~^^^^^^^^^
  File "C:\Users\tefba\Desktop\OverBrand\acadflow\acadflow_env\Lib\site-packages\rest_framework\views.py", line 330, in perform_authentication
    request.user
  File "C:\Users\tefba\Desktop\OverBrand\acadflow\acadflow_env\Lib\site-packages\rest_framework\request.py", line 232, in user
    self._authenticate()
    ~~~~~~~~~~~~~~~~~~^^
  File "C:\Users\tefba\Desktop\OverBrand\acadflow\acadflow_env\Lib\site-packages\rest_framework\request.py", line 385, in _authenticate
    user_auth_tuple = authenticator.authenticate(self)
  File "C:\Users\tefba\Desktop\OverBrand\acadflow\acadflow_env\Lib\site-packages\rest_framework\authentication.py", line 196, in authenticate
    return self.authenticate_credentials(token)
           ~~~~~~~~~~~~~~~~~~~~~~~~~~~~~^^^^^^^
  File "C:\Users\tefba\Desktop\OverBrand\acadflow\acadflow_env\Lib\site-packages\rest_framework\authentication.py", line 201, in authenticate_credentials
    token = model.objects.select_related('user').get(key=key)
  File "C:\Users\tefba\Desktop\OverBrand\acadflow\acadflow_env\Lib\site-packages\django\db\models\query.py", line 629, in get
    num = len(clone)
  File "C:\Users\tefba\Desktop\OverBrand\acadflow\acadflow_env\Lib\site-packages\django\db\models\query.py", line 366, in __len__
    self._fetch_all()
    ~~~~~~~~~~~~~~~^^
  File "C:\Users\tefba\Desktop\OverBrand\acadflow\acadflow_env\Lib\site-packages\django\db\models\query.py", line 1945, in _fetch_all
    self._result_cache = list(self._iterable_class(self))
                         ~~~~^^^^^^^^^^^^^^^^^^^^^^^^^^^^
  File "C:\Users\tefba\Desktop\OverBrand\acadflow\acadflow_env\Lib\site-packages\django\db\models\query.py", line 91, in __iter__
    results = compiler.execute_sql(
        chunked_fetch=self.chunked_fetch, chunk_size=self.chunk_size
    )
  File "C:\Users\tefba\Desktop\OverBrand\acadflow\acadflow_env\Lib\site-packages\django\db\models\sql\compiler.py", line 1623, in execute_sql
    cursor.execute(sql, params)
    ~~~~~~~~~~~~~~^^^^^^^^^^^^^
  File "C:\Users\tefba\Desktop\OverBrand\acadflow\acadflow_env\Lib\site-packages\django\db\backends\utils.py", line 122, in execute
    return super().execute(sql, params)
           ~~~~~~~~~~~~~~~^^^^^^^^^^^^^
  File "C:\Users\tefba\Desktop\OverBrand\acadflow\acadflow_env\Lib\site-packages\django\db\backends\utils.py", line 79, in execute
    return self._execute_with_wrappers(
           ~~~~~~~~~~~~~~~~~~~~~~~~~~~^
        sql, params, many=False, executor=self._execute
        ^^^^^^^^^^^^^^^^^^^^^^^^^^^^^^^^^^^^^^^^^^^^^^^
    )
    ^
  File "C:\Users\tefba\Desktop\OverBrand\acadflow\acadflow_env\Lib\site-packages\django\db\backends\utils.py", line 92, in _execute_with_wrappers
    return executor(sql, params, many, context)
  File "C:\Users\tefba\Desktop\OverBrand\acadflow\acadflow_env\Lib\site-packages\django\db\backends\utils.py", line 100, in _execute
    with self.db.wrap_database_errors:
         ^^^^^^^^^^^^^^^^^^^^^^^^^^^^
  File "C:\Users\tefba\Desktop\OverBrand\acadflow\acadflow_env\Lib\site-packages\django\db\utils.py", line 91, in __exit__
    raise dj_exc_value.with_traceback(traceback) from exc_value
  File "C:\Users\tefba\Desktop\OverBrand\acadflow\acadflow_env\Lib\site-packages\django\db\backends\utils.py", line 105, in _execute
    return self.cursor.execute(sql, params)
           ~~~~~~~~~~~~~~~~~~~^^^^^^^^^^^^^
  File "C:\Users\tefba\Desktop\OverBrand\acadflow\acadflow_env\Lib\site-packages\django\db\backends\sqlite3\base.py", line 360, in execute
    return super().execute(query, params)
           ~~~~~~~~~~~~~~~^^^^^^^^^^^^^^^
django.db.utils.OperationalError: no such table: users
ERROR 2025-06-07 10:42:24,117 basehttp 37916 61528 "GET /api/auth/users/me/ HTTP/1.1" 500 198648
ERROR 2025-06-07 10:44:34,227 log 37916 61528 Internal Server Error: /api/auth/login/
Traceback (most recent call last):
  File "C:\Users\tefba\Desktop\OverBrand\acadflow\acadflow_env\Lib\site-packages\django\db\backends\utils.py", line 105, in _execute
    return self.cursor.execute(sql, params)
           ~~~~~~~~~~~~~~~~~~~^^^^^^^^^^^^^
  File "C:\Users\tefba\Desktop\OverBrand\acadflow\acadflow_env\Lib\site-packages\django\db\backends\sqlite3\base.py", line 360, in execute
    return super().execute(query, params)
           ~~~~~~~~~~~~~~~^^^^^^^^^^^^^^^
sqlite3.OperationalError: no such table: users

The above exception was the direct cause of the following exception:

Traceback (most recent call last):
  File "C:\Users\tefba\Desktop\OverBrand\acadflow\acadflow_env\Lib\site-packages\django\core\handlers\exception.py", line 55, in inner
    response = get_response(request)
  File "C:\Users\tefba\Desktop\OverBrand\acadflow\acadflow_env\Lib\site-packages\django\core\handlers\base.py", line 197, in _get_response
    response = wrapped_callback(request, *callback_args, **callback_kwargs)
  File "C:\Users\tefba\Desktop\OverBrand\acadflow\acadflow_env\Lib\site-packages\django\views\decorators\csrf.py", line 65, in _view_wrapper
    return view_func(request, *args, **kwargs)
  File "C:\Users\tefba\Desktop\OverBrand\acadflow\acadflow_env\Lib\site-packages\django\views\generic\base.py", line 104, in view
    return self.dispatch(request, *args, **kwargs)
           ~~~~~~~~~~~~~^^^^^^^^^^^^^^^^^^^^^^^^^^
  File "C:\Users\tefba\Desktop\OverBrand\acadflow\acadflow_env\Lib\site-packages\rest_framework\views.py", line 515, in dispatch
    response = self.handle_exception(exc)
  File "C:\Users\tefba\Desktop\OverBrand\acadflow\acadflow_env\Lib\site-packages\rest_framework\views.py", line 475, in handle_exception
    self.raise_uncaught_exception(exc)
    ~~~~~~~~~~~~~~~~~~~~~~~~~~~~~^^^^^
  File "C:\Users\tefba\Desktop\OverBrand\acadflow\acadflow_env\Lib\site-packages\rest_framework\views.py", line 486, in raise_uncaught_exception
    raise exc
  File "C:\Users\tefba\Desktop\OverBrand\acadflow\acadflow_env\Lib\site-packages\rest_framework\views.py", line 512, in dispatch
    response = handler(request, *args, **kwargs)
  File "C:\Users\tefba\Desktop\OverBrand\acadflow\acadflow_env\Lib\site-packages\rest_framework\decorators.py", line 50, in handler
    return func(*args, **kwargs)
  File "C:\Users\tefba\Desktop\OverBrand\acadflow\acadflow_backend\users\views.py", line 24, in login_view
    if serializer.is_valid():
       ~~~~~~~~~~~~~~~~~~~^^
  File "C:\Users\tefba\Desktop\OverBrand\acadflow\acadflow_env\Lib\site-packages\rest_framework\serializers.py", line 225, in is_valid
    self._validated_data = self.run_validation(self.initial_data)
                           ~~~~~~~~~~~~~~~~~~~^^^^^^^^^^^^^^^^^^^
  File "C:\Users\tefba\Desktop\OverBrand\acadflow\acadflow_env\Lib\site-packages\rest_framework\serializers.py", line 447, in run_validation
    value = self.validate(value)
  File "C:\Users\tefba\Desktop\OverBrand\acadflow\acadflow_backend\users\serializers.py", line 73, in validate
    user = authenticate(username=username, password=password)
  File "C:\Users\tefba\Desktop\OverBrand\acadflow\acadflow_env\Lib\site-packages\django\views\decorators\debug.py", line 75, in sensitive_variables_wrapper
    return func(*func_args, **func_kwargs)
  File "C:\Users\tefba\Desktop\OverBrand\acadflow\acadflow_env\Lib\site-packages\django\contrib\auth\__init__.py", line 114, in authenticate
    user = backend.authenticate(request, **credentials)
  File "C:\Users\tefba\Desktop\OverBrand\acadflow\acadflow_env\Lib\site-packages\django\contrib\auth\backends.py", line 65, in authenticate
    user = UserModel._default_manager.get_by_natural_key(username)
  File "C:\Users\tefba\Desktop\OverBrand\acadflow\acadflow_env\Lib\site-packages\django\contrib\auth\base_user.py", line 37, in get_by_natural_key
    return self.get(**{self.model.USERNAME_FIELD: username})
           ~~~~~~~~^^^^^^^^^^^^^^^^^^^^^^^^^^^^^^^^^^^^^^^^^
  File "C:\Users\tefba\Desktop\OverBrand\acadflow\acadflow_env\Lib\site-packages\django\db\models\manager.py", line 87, in manager_method
    return getattr(self.get_queryset(), name)(*args, **kwargs)
           ~~~~~~~~~~~~~~~~~~~~~~~~~~~~~~~~~~^^^^^^^^^^^^^^^^^
  File "C:\Users\tefba\Desktop\OverBrand\acadflow\acadflow_env\Lib\site-packages\django\db\models\query.py", line 629, in get
    num = len(clone)
  File "C:\Users\tefba\Desktop\OverBrand\acadflow\acadflow_env\Lib\site-packages\django\db\models\query.py", line 366, in __len__
    self._fetch_all()
    ~~~~~~~~~~~~~~~^^
  File "C:\Users\tefba\Desktop\OverBrand\acadflow\acadflow_env\Lib\site-packages\django\db\models\query.py", line 1945, in _fetch_all
    self._result_cache = list(self._iterable_class(self))
                         ~~~~^^^^^^^^^^^^^^^^^^^^^^^^^^^^
  File "C:\Users\tefba\Desktop\OverBrand\acadflow\acadflow_env\Lib\site-packages\django\db\models\query.py", line 91, in __iter__
    results = compiler.execute_sql(
        chunked_fetch=self.chunked_fetch, chunk_size=self.chunk_size
    )
  File "C:\Users\tefba\Desktop\OverBrand\acadflow\acadflow_env\Lib\site-packages\django\db\models\sql\compiler.py", line 1623, in execute_sql
    cursor.execute(sql, params)
    ~~~~~~~~~~~~~~^^^^^^^^^^^^^
  File "C:\Users\tefba\Desktop\OverBrand\acadflow\acadflow_env\Lib\site-packages\django\db\backends\utils.py", line 122, in execute
    return super().execute(sql, params)
           ~~~~~~~~~~~~~~~^^^^^^^^^^^^^
  File "C:\Users\tefba\Desktop\OverBrand\acadflow\acadflow_env\Lib\site-packages\django\db\backends\utils.py", line 79, in execute
    return self._execute_with_wrappers(
           ~~~~~~~~~~~~~~~~~~~~~~~~~~~^
        sql, params, many=False, executor=self._execute
        ^^^^^^^^^^^^^^^^^^^^^^^^^^^^^^^^^^^^^^^^^^^^^^^
    )
    ^
  File "C:\Users\tefba\Desktop\OverBrand\acadflow\acadflow_env\Lib\site-packages\django\db\backends\utils.py", line 92, in _execute_with_wrappers
    return executor(sql, params, many, context)
  File "C:\Users\tefba\Desktop\OverBrand\acadflow\acadflow_env\Lib\site-packages\django\db\backends\utils.py", line 100, in _execute
    with self.db.wrap_database_errors:
         ^^^^^^^^^^^^^^^^^^^^^^^^^^^^
  File "C:\Users\tefba\Desktop\OverBrand\acadflow\acadflow_env\Lib\site-packages\django\db\utils.py", line 91, in __exit__
    raise dj_exc_value.with_traceback(traceback) from exc_value
  File "C:\Users\tefba\Desktop\OverBrand\acadflow\acadflow_env\Lib\site-packages\django\db\backends\utils.py", line 105, in _execute
    return self.cursor.execute(sql, params)
           ~~~~~~~~~~~~~~~~~~~^^^^^^^^^^^^^
  File "C:\Users\tefba\Desktop\OverBrand\acadflow\acadflow_env\Lib\site-packages\django\db\backends\sqlite3\base.py", line 360, in execute
    return super().execute(query, params)
           ~~~~~~~~~~~~~~~^^^^^^^^^^^^^^^
django.db.utils.OperationalError: no such table: users
ERROR 2025-06-07 10:44:34,231 basehttp 37916 61528 "POST /api/auth/login/ HTTP/1.1" 500 213202
ERROR 2025-06-07 10:44:41,277 log 37916 61528 Internal Server Error: /api/auth/login/
Traceback (most recent call last):
  File "C:\Users\tefba\Desktop\OverBrand\acadflow\acadflow_env\Lib\site-packages\django\db\backends\utils.py", line 105, in _execute
    return self.cursor.execute(sql, params)
           ~~~~~~~~~~~~~~~~~~~^^^^^^^^^^^^^
  File "C:\Users\tefba\Desktop\OverBrand\acadflow\acadflow_env\Lib\site-packages\django\db\backends\sqlite3\base.py", line 360, in execute
    return super().execute(query, params)
           ~~~~~~~~~~~~~~~^^^^^^^^^^^^^^^
sqlite3.OperationalError: no such table: users

The above exception was the direct cause of the following exception:

Traceback (most recent call last):
  File "C:\Users\tefba\Desktop\OverBrand\acadflow\acadflow_env\Lib\site-packages\django\core\handlers\exception.py", line 55, in inner
    response = get_response(request)
  File "C:\Users\tefba\Desktop\OverBrand\acadflow\acadflow_env\Lib\site-packages\django\core\handlers\base.py", line 197, in _get_response
    response = wrapped_callback(request, *callback_args, **callback_kwargs)
  File "C:\Users\tefba\Desktop\OverBrand\acadflow\acadflow_env\Lib\site-packages\django\views\decorators\csrf.py", line 65, in _view_wrapper
    return view_func(request, *args, **kwargs)
  File "C:\Users\tefba\Desktop\OverBrand\acadflow\acadflow_env\Lib\site-packages\django\views\generic\base.py", line 104, in view
    return self.dispatch(request, *args, **kwargs)
           ~~~~~~~~~~~~~^^^^^^^^^^^^^^^^^^^^^^^^^^
  File "C:\Users\tefba\Desktop\OverBrand\acadflow\acadflow_env\Lib\site-packages\rest_framework\views.py", line 515, in dispatch
    response = self.handle_exception(exc)
  File "C:\Users\tefba\Desktop\OverBrand\acadflow\acadflow_env\Lib\site-packages\rest_framework\views.py", line 475, in handle_exception
    self.raise_uncaught_exception(exc)
    ~~~~~~~~~~~~~~~~~~~~~~~~~~~~~^^^^^
  File "C:\Users\tefba\Desktop\OverBrand\acadflow\acadflow_env\Lib\site-packages\rest_framework\views.py", line 486, in raise_uncaught_exception
    raise exc
  File "C:\Users\tefba\Desktop\OverBrand\acadflow\acadflow_env\Lib\site-packages\rest_framework\views.py", line 512, in dispatch
    response = handler(request, *args, **kwargs)
  File "C:\Users\tefba\Desktop\OverBrand\acadflow\acadflow_env\Lib\site-packages\rest_framework\decorators.py", line 50, in handler
    return func(*args, **kwargs)
  File "C:\Users\tefba\Desktop\OverBrand\acadflow\acadflow_backend\users\views.py", line 24, in login_view
    if serializer.is_valid():
       ~~~~~~~~~~~~~~~~~~~^^
  File "C:\Users\tefba\Desktop\OverBrand\acadflow\acadflow_env\Lib\site-packages\rest_framework\serializers.py", line 225, in is_valid
    self._validated_data = self.run_validation(self.initial_data)
                           ~~~~~~~~~~~~~~~~~~~^^^^^^^^^^^^^^^^^^^
  File "C:\Users\tefba\Desktop\OverBrand\acadflow\acadflow_env\Lib\site-packages\rest_framework\serializers.py", line 447, in run_validation
    value = self.validate(value)
  File "C:\Users\tefba\Desktop\OverBrand\acadflow\acadflow_backend\users\serializers.py", line 73, in validate
    user = authenticate(username=username, password=password)
  File "C:\Users\tefba\Desktop\OverBrand\acadflow\acadflow_env\Lib\site-packages\django\views\decorators\debug.py", line 75, in sensitive_variables_wrapper
    return func(*func_args, **func_kwargs)
  File "C:\Users\tefba\Desktop\OverBrand\acadflow\acadflow_env\Lib\site-packages\django\contrib\auth\__init__.py", line 114, in authenticate
    user = backend.authenticate(request, **credentials)
  File "C:\Users\tefba\Desktop\OverBrand\acadflow\acadflow_env\Lib\site-packages\django\contrib\auth\backends.py", line 65, in authenticate
    user = UserModel._default_manager.get_by_natural_key(username)
  File "C:\Users\tefba\Desktop\OverBrand\acadflow\acadflow_env\Lib\site-packages\django\contrib\auth\base_user.py", line 37, in get_by_natural_key
    return self.get(**{self.model.USERNAME_FIELD: username})
           ~~~~~~~~^^^^^^^^^^^^^^^^^^^^^^^^^^^^^^^^^^^^^^^^^
  File "C:\Users\tefba\Desktop\OverBrand\acadflow\acadflow_env\Lib\site-packages\django\db\models\manager.py", line 87, in manager_method
    return getattr(self.get_queryset(), name)(*args, **kwargs)
           ~~~~~~~~~~~~~~~~~~~~~~~~~~~~~~~~~~^^^^^^^^^^^^^^^^^
  File "C:\Users\tefba\Desktop\OverBrand\acadflow\acadflow_env\Lib\site-packages\django\db\models\query.py", line 629, in get
    num = len(clone)
  File "C:\Users\tefba\Desktop\OverBrand\acadflow\acadflow_env\Lib\site-packages\django\db\models\query.py", line 366, in __len__
    self._fetch_all()
    ~~~~~~~~~~~~~~~^^
  File "C:\Users\tefba\Desktop\OverBrand\acadflow\acadflow_env\Lib\site-packages\django\db\models\query.py", line 1945, in _fetch_all
    self._result_cache = list(self._iterable_class(self))
                         ~~~~^^^^^^^^^^^^^^^^^^^^^^^^^^^^
  File "C:\Users\tefba\Desktop\OverBrand\acadflow\acadflow_env\Lib\site-packages\django\db\models\query.py", line 91, in __iter__
    results = compiler.execute_sql(
        chunked_fetch=self.chunked_fetch, chunk_size=self.chunk_size
    )
  File "C:\Users\tefba\Desktop\OverBrand\acadflow\acadflow_env\Lib\site-packages\django\db\models\sql\compiler.py", line 1623, in execute_sql
    cursor.execute(sql, params)
    ~~~~~~~~~~~~~~^^^^^^^^^^^^^
  File "C:\Users\tefba\Desktop\OverBrand\acadflow\acadflow_env\Lib\site-packages\django\db\backends\utils.py", line 122, in execute
    return super().execute(sql, params)
           ~~~~~~~~~~~~~~~^^^^^^^^^^^^^
  File "C:\Users\tefba\Desktop\OverBrand\acadflow\acadflow_env\Lib\site-packages\django\db\backends\utils.py", line 79, in execute
    return self._execute_with_wrappers(
           ~~~~~~~~~~~~~~~~~~~~~~~~~~~^
        sql, params, many=False, executor=self._execute
        ^^^^^^^^^^^^^^^^^^^^^^^^^^^^^^^^^^^^^^^^^^^^^^^
    )
    ^
  File "C:\Users\tefba\Desktop\OverBrand\acadflow\acadflow_env\Lib\site-packages\django\db\backends\utils.py", line 92, in _execute_with_wrappers
    return executor(sql, params, many, context)
  File "C:\Users\tefba\Desktop\OverBrand\acadflow\acadflow_env\Lib\site-packages\django\db\backends\utils.py", line 100, in _execute
    with self.db.wrap_database_errors:
         ^^^^^^^^^^^^^^^^^^^^^^^^^^^^
  File "C:\Users\tefba\Desktop\OverBrand\acadflow\acadflow_env\Lib\site-packages\django\db\utils.py", line 91, in __exit__
    raise dj_exc_value.with_traceback(traceback) from exc_value
  File "C:\Users\tefba\Desktop\OverBrand\acadflow\acadflow_env\Lib\site-packages\django\db\backends\utils.py", line 105, in _execute
    return self.cursor.execute(sql, params)
           ~~~~~~~~~~~~~~~~~~~^^^^^^^^^^^^^
  File "C:\Users\tefba\Desktop\OverBrand\acadflow\acadflow_env\Lib\site-packages\django\db\backends\sqlite3\base.py", line 360, in execute
    return super().execute(query, params)
           ~~~~~~~~~~~~~~~^^^^^^^^^^^^^^^
django.db.utils.OperationalError: no such table: users
ERROR 2025-06-07 10:44:41,280 basehttp 37916 61528 "POST /api/auth/login/ HTTP/1.1" 500 213202
ERROR 2025-06-07 10:44:52,142 log 37916 61528 Internal Server Error: /api/auth/login/
Traceback (most recent call last):
  File "C:\Users\tefba\Desktop\OverBrand\acadflow\acadflow_env\Lib\site-packages\django\db\backends\utils.py", line 105, in _execute
    return self.cursor.execute(sql, params)
           ~~~~~~~~~~~~~~~~~~~^^^^^^^^^^^^^
  File "C:\Users\tefba\Desktop\OverBrand\acadflow\acadflow_env\Lib\site-packages\django\db\backends\sqlite3\base.py", line 360, in execute
    return super().execute(query, params)
           ~~~~~~~~~~~~~~~^^^^^^^^^^^^^^^
sqlite3.OperationalError: no such table: users

The above exception was the direct cause of the following exception:

Traceback (most recent call last):
  File "C:\Users\tefba\Desktop\OverBrand\acadflow\acadflow_env\Lib\site-packages\django\core\handlers\exception.py", line 55, in inner
    response = get_response(request)
  File "C:\Users\tefba\Desktop\OverBrand\acadflow\acadflow_env\Lib\site-packages\django\core\handlers\base.py", line 197, in _get_response
    response = wrapped_callback(request, *callback_args, **callback_kwargs)
  File "C:\Users\tefba\Desktop\OverBrand\acadflow\acadflow_env\Lib\site-packages\django\views\decorators\csrf.py", line 65, in _view_wrapper
    return view_func(request, *args, **kwargs)
  File "C:\Users\tefba\Desktop\OverBrand\acadflow\acadflow_env\Lib\site-packages\django\views\generic\base.py", line 104, in view
    return self.dispatch(request, *args, **kwargs)
           ~~~~~~~~~~~~~^^^^^^^^^^^^^^^^^^^^^^^^^^
  File "C:\Users\tefba\Desktop\OverBrand\acadflow\acadflow_env\Lib\site-packages\rest_framework\views.py", line 515, in dispatch
    response = self.handle_exception(exc)
  File "C:\Users\tefba\Desktop\OverBrand\acadflow\acadflow_env\Lib\site-packages\rest_framework\views.py", line 475, in handle_exception
    self.raise_uncaught_exception(exc)
    ~~~~~~~~~~~~~~~~~~~~~~~~~~~~~^^^^^
  File "C:\Users\tefba\Desktop\OverBrand\acadflow\acadflow_env\Lib\site-packages\rest_framework\views.py", line 486, in raise_uncaught_exception
    raise exc
  File "C:\Users\tefba\Desktop\OverBrand\acadflow\acadflow_env\Lib\site-packages\rest_framework\views.py", line 512, in dispatch
    response = handler(request, *args, **kwargs)
  File "C:\Users\tefba\Desktop\OverBrand\acadflow\acadflow_env\Lib\site-packages\rest_framework\decorators.py", line 50, in handler
    return func(*args, **kwargs)
  File "C:\Users\tefba\Desktop\OverBrand\acadflow\acadflow_backend\users\views.py", line 24, in login_view
    if serializer.is_valid():
       ~~~~~~~~~~~~~~~~~~~^^
  File "C:\Users\tefba\Desktop\OverBrand\acadflow\acadflow_env\Lib\site-packages\rest_framework\serializers.py", line 225, in is_valid
    self._validated_data = self.run_validation(self.initial_data)
                           ~~~~~~~~~~~~~~~~~~~^^^^^^^^^^^^^^^^^^^
  File "C:\Users\tefba\Desktop\OverBrand\acadflow\acadflow_env\Lib\site-packages\rest_framework\serializers.py", line 447, in run_validation
    value = self.validate(value)
  File "C:\Users\tefba\Desktop\OverBrand\acadflow\acadflow_backend\users\serializers.py", line 73, in validate
    user = authenticate(username=username, password=password)
  File "C:\Users\tefba\Desktop\OverBrand\acadflow\acadflow_env\Lib\site-packages\django\views\decorators\debug.py", line 75, in sensitive_variables_wrapper
    return func(*func_args, **func_kwargs)
  File "C:\Users\tefba\Desktop\OverBrand\acadflow\acadflow_env\Lib\site-packages\django\contrib\auth\__init__.py", line 114, in authenticate
    user = backend.authenticate(request, **credentials)
  File "C:\Users\tefba\Desktop\OverBrand\acadflow\acadflow_env\Lib\site-packages\django\contrib\auth\backends.py", line 65, in authenticate
    user = UserModel._default_manager.get_by_natural_key(username)
  File "C:\Users\tefba\Desktop\OverBrand\acadflow\acadflow_env\Lib\site-packages\django\contrib\auth\base_user.py", line 37, in get_by_natural_key
    return self.get(**{self.model.USERNAME_FIELD: username})
           ~~~~~~~~^^^^^^^^^^^^^^^^^^^^^^^^^^^^^^^^^^^^^^^^^
  File "C:\Users\tefba\Desktop\OverBrand\acadflow\acadflow_env\Lib\site-packages\django\db\models\manager.py", line 87, in manager_method
    return getattr(self.get_queryset(), name)(*args, **kwargs)
           ~~~~~~~~~~~~~~~~~~~~~~~~~~~~~~~~~~^^^^^^^^^^^^^^^^^
  File "C:\Users\tefba\Desktop\OverBrand\acadflow\acadflow_env\Lib\site-packages\django\db\models\query.py", line 629, in get
    num = len(clone)
  File "C:\Users\tefba\Desktop\OverBrand\acadflow\acadflow_env\Lib\site-packages\django\db\models\query.py", line 366, in __len__
    self._fetch_all()
    ~~~~~~~~~~~~~~~^^
  File "C:\Users\tefba\Desktop\OverBrand\acadflow\acadflow_env\Lib\site-packages\django\db\models\query.py", line 1945, in _fetch_all
    self._result_cache = list(self._iterable_class(self))
                         ~~~~^^^^^^^^^^^^^^^^^^^^^^^^^^^^
  File "C:\Users\tefba\Desktop\OverBrand\acadflow\acadflow_env\Lib\site-packages\django\db\models\query.py", line 91, in __iter__
    results = compiler.execute_sql(
        chunked_fetch=self.chunked_fetch, chunk_size=self.chunk_size
    )
  File "C:\Users\tefba\Desktop\OverBrand\acadflow\acadflow_env\Lib\site-packages\django\db\models\sql\compiler.py", line 1623, in execute_sql
    cursor.execute(sql, params)
    ~~~~~~~~~~~~~~^^^^^^^^^^^^^
  File "C:\Users\tefba\Desktop\OverBrand\acadflow\acadflow_env\Lib\site-packages\django\db\backends\utils.py", line 122, in execute
    return super().execute(sql, params)
           ~~~~~~~~~~~~~~~^^^^^^^^^^^^^
  File "C:\Users\tefba\Desktop\OverBrand\acadflow\acadflow_env\Lib\site-packages\django\db\backends\utils.py", line 79, in execute
    return self._execute_with_wrappers(
           ~~~~~~~~~~~~~~~~~~~~~~~~~~~^
        sql, params, many=False, executor=self._execute
        ^^^^^^^^^^^^^^^^^^^^^^^^^^^^^^^^^^^^^^^^^^^^^^^
    )
    ^
  File "C:\Users\tefba\Desktop\OverBrand\acadflow\acadflow_env\Lib\site-packages\django\db\backends\utils.py", line 92, in _execute_with_wrappers
    return executor(sql, params, many, context)
  File "C:\Users\tefba\Desktop\OverBrand\acadflow\acadflow_env\Lib\site-packages\django\db\backends\utils.py", line 100, in _execute
    with self.db.wrap_database_errors:
         ^^^^^^^^^^^^^^^^^^^^^^^^^^^^
  File "C:\Users\tefba\Desktop\OverBrand\acadflow\acadflow_env\Lib\site-packages\django\db\utils.py", line 91, in __exit__
    raise dj_exc_value.with_traceback(traceback) from exc_value
  File "C:\Users\tefba\Desktop\OverBrand\acadflow\acadflow_env\Lib\site-packages\django\db\backends\utils.py", line 105, in _execute
    return self.cursor.execute(sql, params)
           ~~~~~~~~~~~~~~~~~~~^^^^^^^^^^^^^
  File "C:\Users\tefba\Desktop\OverBrand\acadflow\acadflow_env\Lib\site-packages\django\db\backends\sqlite3\base.py", line 360, in execute
    return super().execute(query, params)
           ~~~~~~~~~~~~~~~^^^^^^^^^^^^^^^
django.db.utils.OperationalError: no such table: users
ERROR 2025-06-07 10:44:52,146 basehttp 37916 61528 "POST /api/auth/login/ HTTP/1.1" 500 213234
ERROR 2025-06-07 10:45:03,841 log 37916 61528 Internal Server Error: /api/auth/login/
Traceback (most recent call last):
  File "C:\Users\tefba\Desktop\OverBrand\acadflow\acadflow_env\Lib\site-packages\django\db\backends\utils.py", line 105, in _execute
    return self.cursor.execute(sql, params)
           ~~~~~~~~~~~~~~~~~~~^^^^^^^^^^^^^
  File "C:\Users\tefba\Desktop\OverBrand\acadflow\acadflow_env\Lib\site-packages\django\db\backends\sqlite3\base.py", line 360, in execute
    return super().execute(query, params)
           ~~~~~~~~~~~~~~~^^^^^^^^^^^^^^^
sqlite3.OperationalError: no such table: users

The above exception was the direct cause of the following exception:

Traceback (most recent call last):
  File "C:\Users\tefba\Desktop\OverBrand\acadflow\acadflow_env\Lib\site-packages\django\core\handlers\exception.py", line 55, in inner
    response = get_response(request)
  File "C:\Users\tefba\Desktop\OverBrand\acadflow\acadflow_env\Lib\site-packages\django\core\handlers\base.py", line 197, in _get_response
    response = wrapped_callback(request, *callback_args, **callback_kwargs)
  File "C:\Users\tefba\Desktop\OverBrand\acadflow\acadflow_env\Lib\site-packages\django\views\decorators\csrf.py", line 65, in _view_wrapper
    return view_func(request, *args, **kwargs)
  File "C:\Users\tefba\Desktop\OverBrand\acadflow\acadflow_env\Lib\site-packages\django\views\generic\base.py", line 104, in view
    return self.dispatch(request, *args, **kwargs)
           ~~~~~~~~~~~~~^^^^^^^^^^^^^^^^^^^^^^^^^^
  File "C:\Users\tefba\Desktop\OverBrand\acadflow\acadflow_env\Lib\site-packages\rest_framework\views.py", line 515, in dispatch
    response = self.handle_exception(exc)
  File "C:\Users\tefba\Desktop\OverBrand\acadflow\acadflow_env\Lib\site-packages\rest_framework\views.py", line 475, in handle_exception
    self.raise_uncaught_exception(exc)
    ~~~~~~~~~~~~~~~~~~~~~~~~~~~~~^^^^^
  File "C:\Users\tefba\Desktop\OverBrand\acadflow\acadflow_env\Lib\site-packages\rest_framework\views.py", line 486, in raise_uncaught_exception
    raise exc
  File "C:\Users\tefba\Desktop\OverBrand\acadflow\acadflow_env\Lib\site-packages\rest_framework\views.py", line 512, in dispatch
    response = handler(request, *args, **kwargs)
  File "C:\Users\tefba\Desktop\OverBrand\acadflow\acadflow_env\Lib\site-packages\rest_framework\decorators.py", line 50, in handler
    return func(*args, **kwargs)
  File "C:\Users\tefba\Desktop\OverBrand\acadflow\acadflow_backend\users\views.py", line 24, in login_view
    if serializer.is_valid():
       ~~~~~~~~~~~~~~~~~~~^^
  File "C:\Users\tefba\Desktop\OverBrand\acadflow\acadflow_env\Lib\site-packages\rest_framework\serializers.py", line 225, in is_valid
    self._validated_data = self.run_validation(self.initial_data)
                           ~~~~~~~~~~~~~~~~~~~^^^^^^^^^^^^^^^^^^^
  File "C:\Users\tefba\Desktop\OverBrand\acadflow\acadflow_env\Lib\site-packages\rest_framework\serializers.py", line 447, in run_validation
    value = self.validate(value)
  File "C:\Users\tefba\Desktop\OverBrand\acadflow\acadflow_backend\users\serializers.py", line 73, in validate
    user = authenticate(username=username, password=password)
  File "C:\Users\tefba\Desktop\OverBrand\acadflow\acadflow_env\Lib\site-packages\django\views\decorators\debug.py", line 75, in sensitive_variables_wrapper
    return func(*func_args, **func_kwargs)
  File "C:\Users\tefba\Desktop\OverBrand\acadflow\acadflow_env\Lib\site-packages\django\contrib\auth\__init__.py", line 114, in authenticate
    user = backend.authenticate(request, **credentials)
  File "C:\Users\tefba\Desktop\OverBrand\acadflow\acadflow_env\Lib\site-packages\django\contrib\auth\backends.py", line 65, in authenticate
    user = UserModel._default_manager.get_by_natural_key(username)
  File "C:\Users\tefba\Desktop\OverBrand\acadflow\acadflow_env\Lib\site-packages\django\contrib\auth\base_user.py", line 37, in get_by_natural_key
    return self.get(**{self.model.USERNAME_FIELD: username})
           ~~~~~~~~^^^^^^^^^^^^^^^^^^^^^^^^^^^^^^^^^^^^^^^^^
  File "C:\Users\tefba\Desktop\OverBrand\acadflow\acadflow_env\Lib\site-packages\django\db\models\manager.py", line 87, in manager_method
    return getattr(self.get_queryset(), name)(*args, **kwargs)
           ~~~~~~~~~~~~~~~~~~~~~~~~~~~~~~~~~~^^^^^^^^^^^^^^^^^
  File "C:\Users\tefba\Desktop\OverBrand\acadflow\acadflow_env\Lib\site-packages\django\db\models\query.py", line 629, in get
    num = len(clone)
  File "C:\Users\tefba\Desktop\OverBrand\acadflow\acadflow_env\Lib\site-packages\django\db\models\query.py", line 366, in __len__
    self._fetch_all()
    ~~~~~~~~~~~~~~~^^
  File "C:\Users\tefba\Desktop\OverBrand\acadflow\acadflow_env\Lib\site-packages\django\db\models\query.py", line 1945, in _fetch_all
    self._result_cache = list(self._iterable_class(self))
                         ~~~~^^^^^^^^^^^^^^^^^^^^^^^^^^^^
  File "C:\Users\tefba\Desktop\OverBrand\acadflow\acadflow_env\Lib\site-packages\django\db\models\query.py", line 91, in __iter__
    results = compiler.execute_sql(
        chunked_fetch=self.chunked_fetch, chunk_size=self.chunk_size
    )
  File "C:\Users\tefba\Desktop\OverBrand\acadflow\acadflow_env\Lib\site-packages\django\db\models\sql\compiler.py", line 1623, in execute_sql
    cursor.execute(sql, params)
    ~~~~~~~~~~~~~~^^^^^^^^^^^^^
  File "C:\Users\tefba\Desktop\OverBrand\acadflow\acadflow_env\Lib\site-packages\django\db\backends\utils.py", line 122, in execute
    return super().execute(sql, params)
           ~~~~~~~~~~~~~~~^^^^^^^^^^^^^
  File "C:\Users\tefba\Desktop\OverBrand\acadflow\acadflow_env\Lib\site-packages\django\db\backends\utils.py", line 79, in execute
    return self._execute_with_wrappers(
           ~~~~~~~~~~~~~~~~~~~~~~~~~~~^
        sql, params, many=False, executor=self._execute
        ^^^^^^^^^^^^^^^^^^^^^^^^^^^^^^^^^^^^^^^^^^^^^^^
    )
    ^
  File "C:\Users\tefba\Desktop\OverBrand\acadflow\acadflow_env\Lib\site-packages\django\db\backends\utils.py", line 92, in _execute_with_wrappers
    return executor(sql, params, many, context)
  File "C:\Users\tefba\Desktop\OverBrand\acadflow\acadflow_env\Lib\site-packages\django\db\backends\utils.py", line 100, in _execute
    with self.db.wrap_database_errors:
         ^^^^^^^^^^^^^^^^^^^^^^^^^^^^
  File "C:\Users\tefba\Desktop\OverBrand\acadflow\acadflow_env\Lib\site-packages\django\db\utils.py", line 91, in __exit__
    raise dj_exc_value.with_traceback(traceback) from exc_value
  File "C:\Users\tefba\Desktop\OverBrand\acadflow\acadflow_env\Lib\site-packages\django\db\backends\utils.py", line 105, in _execute
    return self.cursor.execute(sql, params)
           ~~~~~~~~~~~~~~~~~~~^^^^^^^^^^^^^
  File "C:\Users\tefba\Desktop\OverBrand\acadflow\acadflow_env\Lib\site-packages\django\db\backends\sqlite3\base.py", line 360, in execute
    return super().execute(query, params)
           ~~~~~~~~~~~~~~~^^^^^^^^^^^^^^^
django.db.utils.OperationalError: no such table: users
ERROR 2025-06-07 10:45:03,844 basehttp 37916 61528 "POST /api/auth/login/ HTTP/1.1" 500 213214
ERROR 2025-06-07 10:46:40,250 log 37916 61528 Internal Server Error: /api/auth/users/me/
Traceback (most recent call last):
  File "C:\Users\tefba\Desktop\OverBrand\acadflow\acadflow_env\Lib\site-packages\django\db\backends\utils.py", line 105, in _execute
    return self.cursor.execute(sql, params)
           ~~~~~~~~~~~~~~~~~~~^^^^^^^^^^^^^
  File "C:\Users\tefba\Desktop\OverBrand\acadflow\acadflow_env\Lib\site-packages\django\db\backends\sqlite3\base.py", line 360, in execute
    return super().execute(query, params)
           ~~~~~~~~~~~~~~~^^^^^^^^^^^^^^^
sqlite3.OperationalError: no such table: users

The above exception was the direct cause of the following exception:

Traceback (most recent call last):
  File "C:\Users\tefba\Desktop\OverBrand\acadflow\acadflow_env\Lib\site-packages\django\core\handlers\exception.py", line 55, in inner
    response = get_response(request)
  File "C:\Users\tefba\Desktop\OverBrand\acadflow\acadflow_env\Lib\site-packages\django\core\handlers\base.py", line 197, in _get_response
    response = wrapped_callback(request, *callback_args, **callback_kwargs)
  File "C:\Users\tefba\Desktop\OverBrand\acadflow\acadflow_env\Lib\site-packages\django\views\decorators\csrf.py", line 65, in _view_wrapper
    return view_func(request, *args, **kwargs)
  File "C:\Users\tefba\Desktop\OverBrand\acadflow\acadflow_env\Lib\site-packages\rest_framework\viewsets.py", line 125, in view
    return self.dispatch(request, *args, **kwargs)
           ~~~~~~~~~~~~~^^^^^^^^^^^^^^^^^^^^^^^^^^
  File "C:\Users\tefba\Desktop\OverBrand\acadflow\acadflow_env\Lib\site-packages\rest_framework\views.py", line 515, in dispatch
    response = self.handle_exception(exc)
  File "C:\Users\tefba\Desktop\OverBrand\acadflow\acadflow_env\Lib\site-packages\rest_framework\views.py", line 475, in handle_exception
    self.raise_uncaught_exception(exc)
    ~~~~~~~~~~~~~~~~~~~~~~~~~~~~~^^^^^
  File "C:\Users\tefba\Desktop\OverBrand\acadflow\acadflow_env\Lib\site-packages\rest_framework\views.py", line 486, in raise_uncaught_exception
    raise exc
  File "C:\Users\tefba\Desktop\OverBrand\acadflow\acadflow_env\Lib\site-packages\rest_framework\views.py", line 503, in dispatch
    self.initial(request, *args, **kwargs)
    ~~~~~~~~~~~~^^^^^^^^^^^^^^^^^^^^^^^^^^
  File "C:\Users\tefba\Desktop\OverBrand\acadflow\acadflow_env\Lib\site-packages\rest_framework\views.py", line 420, in initial
    self.perform_authentication(request)
    ~~~~~~~~~~~~~~~~~~~~~~~~~~~^^^^^^^^^
  File "C:\Users\tefba\Desktop\OverBrand\acadflow\acadflow_env\Lib\site-packages\rest_framework\views.py", line 330, in perform_authentication
    request.user
  File "C:\Users\tefba\Desktop\OverBrand\acadflow\acadflow_env\Lib\site-packages\rest_framework\request.py", line 232, in user
    self._authenticate()
    ~~~~~~~~~~~~~~~~~~^^
  File "C:\Users\tefba\Desktop\OverBrand\acadflow\acadflow_env\Lib\site-packages\rest_framework\request.py", line 385, in _authenticate
    user_auth_tuple = authenticator.authenticate(self)
  File "C:\Users\tefba\Desktop\OverBrand\acadflow\acadflow_env\Lib\site-packages\rest_framework\authentication.py", line 196, in authenticate
    return self.authenticate_credentials(token)
           ~~~~~~~~~~~~~~~~~~~~~~~~~~~~~^^^^^^^
  File "C:\Users\tefba\Desktop\OverBrand\acadflow\acadflow_env\Lib\site-packages\rest_framework\authentication.py", line 201, in authenticate_credentials
    token = model.objects.select_related('user').get(key=key)
  File "C:\Users\tefba\Desktop\OverBrand\acadflow\acadflow_env\Lib\site-packages\django\db\models\query.py", line 629, in get
    num = len(clone)
  File "C:\Users\tefba\Desktop\OverBrand\acadflow\acadflow_env\Lib\site-packages\django\db\models\query.py", line 366, in __len__
    self._fetch_all()
    ~~~~~~~~~~~~~~~^^
  File "C:\Users\tefba\Desktop\OverBrand\acadflow\acadflow_env\Lib\site-packages\django\db\models\query.py", line 1945, in _fetch_all
    self._result_cache = list(self._iterable_class(self))
                         ~~~~^^^^^^^^^^^^^^^^^^^^^^^^^^^^
  File "C:\Users\tefba\Desktop\OverBrand\acadflow\acadflow_env\Lib\site-packages\django\db\models\query.py", line 91, in __iter__
    results = compiler.execute_sql(
        chunked_fetch=self.chunked_fetch, chunk_size=self.chunk_size
    )
  File "C:\Users\tefba\Desktop\OverBrand\acadflow\acadflow_env\Lib\site-packages\django\db\models\sql\compiler.py", line 1623, in execute_sql
    cursor.execute(sql, params)
    ~~~~~~~~~~~~~~^^^^^^^^^^^^^
  File "C:\Users\tefba\Desktop\OverBrand\acadflow\acadflow_env\Lib\site-packages\django\db\backends\utils.py", line 122, in execute
    return super().execute(sql, params)
           ~~~~~~~~~~~~~~~^^^^^^^^^^^^^
  File "C:\Users\tefba\Desktop\OverBrand\acadflow\acadflow_env\Lib\site-packages\django\db\backends\utils.py", line 79, in execute
    return self._execute_with_wrappers(
           ~~~~~~~~~~~~~~~~~~~~~~~~~~~^
        sql, params, many=False, executor=self._execute
        ^^^^^^^^^^^^^^^^^^^^^^^^^^^^^^^^^^^^^^^^^^^^^^^
    )
    ^
  File "C:\Users\tefba\Desktop\OverBrand\acadflow\acadflow_env\Lib\site-packages\django\db\backends\utils.py", line 92, in _execute_with_wrappers
    return executor(sql, params, many, context)
  File "C:\Users\tefba\Desktop\OverBrand\acadflow\acadflow_env\Lib\site-packages\django\db\backends\utils.py", line 100, in _execute
    with self.db.wrap_database_errors:
         ^^^^^^^^^^^^^^^^^^^^^^^^^^^^
  File "C:\Users\tefba\Desktop\OverBrand\acadflow\acadflow_env\Lib\site-packages\django\db\utils.py", line 91, in __exit__
    raise dj_exc_value.with_traceback(traceback) from exc_value
  File "C:\Users\tefba\Desktop\OverBrand\acadflow\acadflow_env\Lib\site-packages\django\db\backends\utils.py", line 105, in _execute
    return self.cursor.execute(sql, params)
           ~~~~~~~~~~~~~~~~~~~^^^^^^^^^^^^^
  File "C:\Users\tefba\Desktop\OverBrand\acadflow\acadflow_env\Lib\site-packages\django\db\backends\sqlite3\base.py", line 360, in execute
    return super().execute(query, params)
           ~~~~~~~~~~~~~~~^^^^^^^^^^^^^^^
django.db.utils.OperationalError: no such table: users
ERROR 2025-06-07 10:46:40,256 basehttp 37916 61528 "GET /api/auth/users/me/ HTTP/1.1" 500 198648
ERROR 2025-06-07 16:31:37,980 log 37916 26700 Internal Server Error: /api/auth/login/
Traceback (most recent call last):
  File "C:\Users\tefba\Desktop\OverBrand\acadflow\acadflow_env\Lib\site-packages\django\db\backends\utils.py", line 105, in _execute
    return self.cursor.execute(sql, params)
           ~~~~~~~~~~~~~~~~~~~^^^^^^^^^^^^^
  File "C:\Users\tefba\Desktop\OverBrand\acadflow\acadflow_env\Lib\site-packages\django\db\backends\sqlite3\base.py", line 360, in execute
    return super().execute(query, params)
           ~~~~~~~~~~~~~~~^^^^^^^^^^^^^^^
sqlite3.OperationalError: no such table: users

The above exception was the direct cause of the following exception:

Traceback (most recent call last):
  File "C:\Users\tefba\Desktop\OverBrand\acadflow\acadflow_env\Lib\site-packages\django\core\handlers\exception.py", line 55, in inner
    response = get_response(request)
  File "C:\Users\tefba\Desktop\OverBrand\acadflow\acadflow_env\Lib\site-packages\django\core\handlers\base.py", line 197, in _get_response
    response = wrapped_callback(request, *callback_args, **callback_kwargs)
  File "C:\Users\tefba\Desktop\OverBrand\acadflow\acadflow_env\Lib\site-packages\django\views\decorators\csrf.py", line 65, in _view_wrapper
    return view_func(request, *args, **kwargs)
  File "C:\Users\tefba\Desktop\OverBrand\acadflow\acadflow_env\Lib\site-packages\django\views\generic\base.py", line 104, in view
    return self.dispatch(request, *args, **kwargs)
           ~~~~~~~~~~~~~^^^^^^^^^^^^^^^^^^^^^^^^^^
  File "C:\Users\tefba\Desktop\OverBrand\acadflow\acadflow_env\Lib\site-packages\rest_framework\views.py", line 515, in dispatch
    response = self.handle_exception(exc)
  File "C:\Users\tefba\Desktop\OverBrand\acadflow\acadflow_env\Lib\site-packages\rest_framework\views.py", line 475, in handle_exception
    self.raise_uncaught_exception(exc)
    ~~~~~~~~~~~~~~~~~~~~~~~~~~~~~^^^^^
  File "C:\Users\tefba\Desktop\OverBrand\acadflow\acadflow_env\Lib\site-packages\rest_framework\views.py", line 486, in raise_uncaught_exception
    raise exc
  File "C:\Users\tefba\Desktop\OverBrand\acadflow\acadflow_env\Lib\site-packages\rest_framework\views.py", line 512, in dispatch
    response = handler(request, *args, **kwargs)
  File "C:\Users\tefba\Desktop\OverBrand\acadflow\acadflow_env\Lib\site-packages\rest_framework\decorators.py", line 50, in handler
    return func(*args, **kwargs)
  File "C:\Users\tefba\Desktop\OverBrand\acadflow\acadflow_backend\users\views.py", line 24, in login_view
    if serializer.is_valid():
       ~~~~~~~~~~~~~~~~~~~^^
  File "C:\Users\tefba\Desktop\OverBrand\acadflow\acadflow_env\Lib\site-packages\rest_framework\serializers.py", line 225, in is_valid
    self._validated_data = self.run_validation(self.initial_data)
                           ~~~~~~~~~~~~~~~~~~~^^^^^^^^^^^^^^^^^^^
  File "C:\Users\tefba\Desktop\OverBrand\acadflow\acadflow_env\Lib\site-packages\rest_framework\serializers.py", line 447, in run_validation
    value = self.validate(value)
  File "C:\Users\tefba\Desktop\OverBrand\acadflow\acadflow_backend\users\serializers.py", line 73, in validate
    user = authenticate(username=username, password=password)
  File "C:\Users\tefba\Desktop\OverBrand\acadflow\acadflow_env\Lib\site-packages\django\views\decorators\debug.py", line 75, in sensitive_variables_wrapper
    return func(*func_args, **func_kwargs)
  File "C:\Users\tefba\Desktop\OverBrand\acadflow\acadflow_env\Lib\site-packages\django\contrib\auth\__init__.py", line 114, in authenticate
    user = backend.authenticate(request, **credentials)
  File "C:\Users\tefba\Desktop\OverBrand\acadflow\acadflow_env\Lib\site-packages\django\contrib\auth\backends.py", line 65, in authenticate
    user = UserModel._default_manager.get_by_natural_key(username)
  File "C:\Users\tefba\Desktop\OverBrand\acadflow\acadflow_env\Lib\site-packages\django\contrib\auth\base_user.py", line 37, in get_by_natural_key
    return self.get(**{self.model.USERNAME_FIELD: username})
           ~~~~~~~~^^^^^^^^^^^^^^^^^^^^^^^^^^^^^^^^^^^^^^^^^
  File "C:\Users\tefba\Desktop\OverBrand\acadflow\acadflow_env\Lib\site-packages\django\db\models\manager.py", line 87, in manager_method
    return getattr(self.get_queryset(), name)(*args, **kwargs)
           ~~~~~~~~~~~~~~~~~~~~~~~~~~~~~~~~~~^^^^^^^^^^^^^^^^^
  File "C:\Users\tefba\Desktop\OverBrand\acadflow\acadflow_env\Lib\site-packages\django\db\models\query.py", line 629, in get
    num = len(clone)
  File "C:\Users\tefba\Desktop\OverBrand\acadflow\acadflow_env\Lib\site-packages\django\db\models\query.py", line 366, in __len__
    self._fetch_all()
    ~~~~~~~~~~~~~~~^^
  File "C:\Users\tefba\Desktop\OverBrand\acadflow\acadflow_env\Lib\site-packages\django\db\models\query.py", line 1945, in _fetch_all
    self._result_cache = list(self._iterable_class(self))
                         ~~~~^^^^^^^^^^^^^^^^^^^^^^^^^^^^
  File "C:\Users\tefba\Desktop\OverBrand\acadflow\acadflow_env\Lib\site-packages\django\db\models\query.py", line 91, in __iter__
    results = compiler.execute_sql(
        chunked_fetch=self.chunked_fetch, chunk_size=self.chunk_size
    )
  File "C:\Users\tefba\Desktop\OverBrand\acadflow\acadflow_env\Lib\site-packages\django\db\models\sql\compiler.py", line 1623, in execute_sql
    cursor.execute(sql, params)
    ~~~~~~~~~~~~~~^^^^^^^^^^^^^
  File "C:\Users\tefba\Desktop\OverBrand\acadflow\acadflow_env\Lib\site-packages\django\db\backends\utils.py", line 122, in execute
    return super().execute(sql, params)
           ~~~~~~~~~~~~~~~^^^^^^^^^^^^^
  File "C:\Users\tefba\Desktop\OverBrand\acadflow\acadflow_env\Lib\site-packages\django\db\backends\utils.py", line 79, in execute
    return self._execute_with_wrappers(
           ~~~~~~~~~~~~~~~~~~~~~~~~~~~^
        sql, params, many=False, executor=self._execute
        ^^^^^^^^^^^^^^^^^^^^^^^^^^^^^^^^^^^^^^^^^^^^^^^
    )
    ^
  File "C:\Users\tefba\Desktop\OverBrand\acadflow\acadflow_env\Lib\site-packages\django\db\backends\utils.py", line 92, in _execute_with_wrappers
    return executor(sql, params, many, context)
  File "C:\Users\tefba\Desktop\OverBrand\acadflow\acadflow_env\Lib\site-packages\django\db\backends\utils.py", line 100, in _execute
    with self.db.wrap_database_errors:
         ^^^^^^^^^^^^^^^^^^^^^^^^^^^^
  File "C:\Users\tefba\Desktop\OverBrand\acadflow\acadflow_env\Lib\site-packages\django\db\utils.py", line 91, in __exit__
    raise dj_exc_value.with_traceback(traceback) from exc_value
  File "C:\Users\tefba\Desktop\OverBrand\acadflow\acadflow_env\Lib\site-packages\django\db\backends\utils.py", line 105, in _execute
    return self.cursor.execute(sql, params)
           ~~~~~~~~~~~~~~~~~~~^^^^^^^^^^^^^
  File "C:\Users\tefba\Desktop\OverBrand\acadflow\acadflow_env\Lib\site-packages\django\db\backends\sqlite3\base.py", line 360, in execute
    return super().execute(query, params)
           ~~~~~~~~~~~~~~~^^^^^^^^^^^^^^^
django.db.utils.OperationalError: no such table: users
ERROR 2025-06-07 16:31:37,984 basehttp 37916 26700 "POST /api/auth/login/ HTTP/1.1" 500 213234
ERROR 2025-06-07 16:31:53,717 log 37916 26700 Internal Server Error: /api/auth/login/
Traceback (most recent call last):
  File "C:\Users\tefba\Desktop\OverBrand\acadflow\acadflow_env\Lib\site-packages\django\db\backends\utils.py", line 105, in _execute
    return self.cursor.execute(sql, params)
           ~~~~~~~~~~~~~~~~~~~^^^^^^^^^^^^^
  File "C:\Users\tefba\Desktop\OverBrand\acadflow\acadflow_env\Lib\site-packages\django\db\backends\sqlite3\base.py", line 360, in execute
    return super().execute(query, params)
           ~~~~~~~~~~~~~~~^^^^^^^^^^^^^^^
sqlite3.OperationalError: no such table: users

The above exception was the direct cause of the following exception:

Traceback (most recent call last):
  File "C:\Users\tefba\Desktop\OverBrand\acadflow\acadflow_env\Lib\site-packages\django\core\handlers\exception.py", line 55, in inner
    response = get_response(request)
  File "C:\Users\tefba\Desktop\OverBrand\acadflow\acadflow_env\Lib\site-packages\django\core\handlers\base.py", line 197, in _get_response
    response = wrapped_callback(request, *callback_args, **callback_kwargs)
  File "C:\Users\tefba\Desktop\OverBrand\acadflow\acadflow_env\Lib\site-packages\django\views\decorators\csrf.py", line 65, in _view_wrapper
    return view_func(request, *args, **kwargs)
  File "C:\Users\tefba\Desktop\OverBrand\acadflow\acadflow_env\Lib\site-packages\django\views\generic\base.py", line 104, in view
    return self.dispatch(request, *args, **kwargs)
           ~~~~~~~~~~~~~^^^^^^^^^^^^^^^^^^^^^^^^^^
  File "C:\Users\tefba\Desktop\OverBrand\acadflow\acadflow_env\Lib\site-packages\rest_framework\views.py", line 515, in dispatch
    response = self.handle_exception(exc)
  File "C:\Users\tefba\Desktop\OverBrand\acadflow\acadflow_env\Lib\site-packages\rest_framework\views.py", line 475, in handle_exception
    self.raise_uncaught_exception(exc)
    ~~~~~~~~~~~~~~~~~~~~~~~~~~~~~^^^^^
  File "C:\Users\tefba\Desktop\OverBrand\acadflow\acadflow_env\Lib\site-packages\rest_framework\views.py", line 486, in raise_uncaught_exception
    raise exc
  File "C:\Users\tefba\Desktop\OverBrand\acadflow\acadflow_env\Lib\site-packages\rest_framework\views.py", line 512, in dispatch
    response = handler(request, *args, **kwargs)
  File "C:\Users\tefba\Desktop\OverBrand\acadflow\acadflow_env\Lib\site-packages\rest_framework\decorators.py", line 50, in handler
    return func(*args, **kwargs)
  File "C:\Users\tefba\Desktop\OverBrand\acadflow\acadflow_backend\users\views.py", line 24, in login_view
    if serializer.is_valid():
       ~~~~~~~~~~~~~~~~~~~^^
  File "C:\Users\tefba\Desktop\OverBrand\acadflow\acadflow_env\Lib\site-packages\rest_framework\serializers.py", line 225, in is_valid
    self._validated_data = self.run_validation(self.initial_data)
                           ~~~~~~~~~~~~~~~~~~~^^^^^^^^^^^^^^^^^^^
  File "C:\Users\tefba\Desktop\OverBrand\acadflow\acadflow_env\Lib\site-packages\rest_framework\serializers.py", line 447, in run_validation
    value = self.validate(value)
  File "C:\Users\tefba\Desktop\OverBrand\acadflow\acadflow_backend\users\serializers.py", line 73, in validate
    user = authenticate(username=username, password=password)
  File "C:\Users\tefba\Desktop\OverBrand\acadflow\acadflow_env\Lib\site-packages\django\views\decorators\debug.py", line 75, in sensitive_variables_wrapper
    return func(*func_args, **func_kwargs)
  File "C:\Users\tefba\Desktop\OverBrand\acadflow\acadflow_env\Lib\site-packages\django\contrib\auth\__init__.py", line 114, in authenticate
    user = backend.authenticate(request, **credentials)
  File "C:\Users\tefba\Desktop\OverBrand\acadflow\acadflow_env\Lib\site-packages\django\contrib\auth\backends.py", line 65, in authenticate
    user = UserModel._default_manager.get_by_natural_key(username)
  File "C:\Users\tefba\Desktop\OverBrand\acadflow\acadflow_env\Lib\site-packages\django\contrib\auth\base_user.py", line 37, in get_by_natural_key
    return self.get(**{self.model.USERNAME_FIELD: username})
           ~~~~~~~~^^^^^^^^^^^^^^^^^^^^^^^^^^^^^^^^^^^^^^^^^
  File "C:\Users\tefba\Desktop\OverBrand\acadflow\acadflow_env\Lib\site-packages\django\db\models\manager.py", line 87, in manager_method
    return getattr(self.get_queryset(), name)(*args, **kwargs)
           ~~~~~~~~~~~~~~~~~~~~~~~~~~~~~~~~~~^^^^^^^^^^^^^^^^^
  File "C:\Users\tefba\Desktop\OverBrand\acadflow\acadflow_env\Lib\site-packages\django\db\models\query.py", line 629, in get
    num = len(clone)
  File "C:\Users\tefba\Desktop\OverBrand\acadflow\acadflow_env\Lib\site-packages\django\db\models\query.py", line 366, in __len__
    self._fetch_all()
    ~~~~~~~~~~~~~~~^^
  File "C:\Users\tefba\Desktop\OverBrand\acadflow\acadflow_env\Lib\site-packages\django\db\models\query.py", line 1945, in _fetch_all
    self._result_cache = list(self._iterable_class(self))
                         ~~~~^^^^^^^^^^^^^^^^^^^^^^^^^^^^
  File "C:\Users\tefba\Desktop\OverBrand\acadflow\acadflow_env\Lib\site-packages\django\db\models\query.py", line 91, in __iter__
    results = compiler.execute_sql(
        chunked_fetch=self.chunked_fetch, chunk_size=self.chunk_size
    )
  File "C:\Users\tefba\Desktop\OverBrand\acadflow\acadflow_env\Lib\site-packages\django\db\models\sql\compiler.py", line 1623, in execute_sql
    cursor.execute(sql, params)
    ~~~~~~~~~~~~~~^^^^^^^^^^^^^
  File "C:\Users\tefba\Desktop\OverBrand\acadflow\acadflow_env\Lib\site-packages\django\db\backends\utils.py", line 122, in execute
    return super().execute(sql, params)
           ~~~~~~~~~~~~~~~^^^^^^^^^^^^^
  File "C:\Users\tefba\Desktop\OverBrand\acadflow\acadflow_env\Lib\site-packages\django\db\backends\utils.py", line 79, in execute
    return self._execute_with_wrappers(
           ~~~~~~~~~~~~~~~~~~~~~~~~~~~^
        sql, params, many=False, executor=self._execute
        ^^^^^^^^^^^^^^^^^^^^^^^^^^^^^^^^^^^^^^^^^^^^^^^
    )
    ^
  File "C:\Users\tefba\Desktop\OverBrand\acadflow\acadflow_env\Lib\site-packages\django\db\backends\utils.py", line 92, in _execute_with_wrappers
    return executor(sql, params, many, context)
  File "C:\Users\tefba\Desktop\OverBrand\acadflow\acadflow_env\Lib\site-packages\django\db\backends\utils.py", line 100, in _execute
    with self.db.wrap_database_errors:
         ^^^^^^^^^^^^^^^^^^^^^^^^^^^^
  File "C:\Users\tefba\Desktop\OverBrand\acadflow\acadflow_env\Lib\site-packages\django\db\utils.py", line 91, in __exit__
    raise dj_exc_value.with_traceback(traceback) from exc_value
  File "C:\Users\tefba\Desktop\OverBrand\acadflow\acadflow_env\Lib\site-packages\django\db\backends\utils.py", line 105, in _execute
    return self.cursor.execute(sql, params)
           ~~~~~~~~~~~~~~~~~~~^^^^^^^^^^^^^
  File "C:\Users\tefba\Desktop\OverBrand\acadflow\acadflow_env\Lib\site-packages\django\db\backends\sqlite3\base.py", line 360, in execute
    return super().execute(query, params)
           ~~~~~~~~~~~~~~~^^^^^^^^^^^^^^^
django.db.utils.OperationalError: no such table: users
ERROR 2025-06-07 16:31:53,721 basehttp 37916 26700 "POST /api/auth/login/ HTTP/1.1" 500 213240
ERROR 2025-06-07 16:37:12,262 log 37916 51372 Internal Server Error: /admin/login/
Traceback (most recent call last):
  File "C:\Users\tefba\Desktop\OverBrand\acadflow\acadflow_env\Lib\site-packages\django\db\backends\utils.py", line 105, in _execute
    return self.cursor.execute(sql, params)
           ~~~~~~~~~~~~~~~~~~~^^^^^^^^^^^^^
  File "C:\Users\tefba\Desktop\OverBrand\acadflow\acadflow_env\Lib\site-packages\django\db\backends\sqlite3\base.py", line 360, in execute
    return super().execute(query, params)
           ~~~~~~~~~~~~~~~^^^^^^^^^^^^^^^
sqlite3.OperationalError: no such table: users

The above exception was the direct cause of the following exception:

Traceback (most recent call last):
  File "C:\Users\tefba\Desktop\OverBrand\acadflow\acadflow_env\Lib\site-packages\django\core\handlers\exception.py", line 55, in inner
    response = get_response(request)
  File "C:\Users\tefba\Desktop\OverBrand\acadflow\acadflow_env\Lib\site-packages\django\core\handlers\base.py", line 197, in _get_response
    response = wrapped_callback(request, *callback_args, **callback_kwargs)
  File "C:\Users\tefba\Desktop\OverBrand\acadflow\acadflow_env\Lib\site-packages\django\utils\decorators.py", line 48, in _wrapper
    return bound_method(*args, **kwargs)
  File "C:\Users\tefba\Desktop\OverBrand\acadflow\acadflow_env\Lib\site-packages\django\views\decorators\cache.py", line 80, in _view_wrapper
    response = view_func(request, *args, **kwargs)
  File "C:\Users\tefba\Desktop\OverBrand\acadflow\acadflow_env\Lib\site-packages\django\contrib\admin\sites.py", line 449, in login
    return LoginView.as_view(**defaults)(request)
           ~~~~~~~~~~~~~~~~~~~~~~~~~~~~~^^^^^^^^^
  File "C:\Users\tefba\Desktop\OverBrand\acadflow\acadflow_env\Lib\site-packages\django\views\generic\base.py", line 104, in view
    return self.dispatch(request, *args, **kwargs)
           ~~~~~~~~~~~~~^^^^^^^^^^^^^^^^^^^^^^^^^^
  File "C:\Users\tefba\Desktop\OverBrand\acadflow\acadflow_env\Lib\site-packages\django\utils\decorators.py", line 48, in _wrapper
    return bound_method(*args, **kwargs)
  File "C:\Users\tefba\Desktop\OverBrand\acadflow\acadflow_env\Lib\site-packages\django\utils\decorators.py", line 48, in _wrapper
    return bound_method(*args, **kwargs)
  File "C:\Users\tefba\Desktop\OverBrand\acadflow\acadflow_env\Lib\site-packages\django\views\decorators\debug.py", line 143, in sensitive_post_parameters_wrapper
    return view(request, *args, **kwargs)
  File "C:\Users\tefba\Desktop\OverBrand\acadflow\acadflow_env\Lib\site-packages\django\utils\decorators.py", line 48, in _wrapper
    return bound_method(*args, **kwargs)
  File "C:\Users\tefba\Desktop\OverBrand\acadflow\acadflow_env\Lib\site-packages\django\utils\decorators.py", line 192, in _view_wrapper
    result = _process_exception(request, e)
  File "C:\Users\tefba\Desktop\OverBrand\acadflow\acadflow_env\Lib\site-packages\django\utils\decorators.py", line 190, in _view_wrapper
    response = view_func(request, *args, **kwargs)
  File "C:\Users\tefba\Desktop\OverBrand\acadflow\acadflow_env\Lib\site-packages\django\utils\decorators.py", line 48, in _wrapper
    return bound_method(*args, **kwargs)
  File "C:\Users\tefba\Desktop\OverBrand\acadflow\acadflow_env\Lib\site-packages\django\views\decorators\cache.py", line 80, in _view_wrapper
    response = view_func(request, *args, **kwargs)
  File "C:\Users\tefba\Desktop\OverBrand\acadflow\acadflow_env\Lib\site-packages\django\contrib\auth\views.py", line 89, in dispatch
    return super().dispatch(request, *args, **kwargs)
           ~~~~~~~~~~~~~~~~^^^^^^^^^^^^^^^^^^^^^^^^^^
  File "C:\Users\tefba\Desktop\OverBrand\acadflow\acadflow_env\Lib\site-packages\django\views\generic\base.py", line 143, in dispatch
    return handler(request, *args, **kwargs)
  File "C:\Users\tefba\Desktop\OverBrand\acadflow\acadflow_env\Lib\site-packages\django\views\generic\edit.py", line 150, in post
    if form.is_valid():
       ~~~~~~~~~~~~~^^
  File "C:\Users\tefba\Desktop\OverBrand\acadflow\acadflow_env\Lib\site-packages\django\forms\forms.py", line 206, in is_valid
    return self.is_bound and not self.errors
                                 ^^^^^^^^^^^
  File "C:\Users\tefba\Desktop\OverBrand\acadflow\acadflow_env\Lib\site-packages\django\forms\forms.py", line 201, in errors
    self.full_clean()
    ~~~~~~~~~~~~~~~^^
  File "C:\Users\tefba\Desktop\OverBrand\acadflow\acadflow_env\Lib\site-packages\django\forms\forms.py", line 338, in full_clean
    self._clean_form()
    ~~~~~~~~~~~~~~~~^^
  File "C:\Users\tefba\Desktop\OverBrand\acadflow\acadflow_env\Lib\site-packages\django\forms\forms.py", line 354, in _clean_form
    cleaned_data = self.clean()
  File "C:\Users\tefba\Desktop\OverBrand\acadflow\acadflow_env\Lib\site-packages\django\views\decorators\debug.py", line 75, in sensitive_variables_wrapper
    return func(*func_args, **func_kwargs)
  File "C:\Users\tefba\Desktop\OverBrand\acadflow\acadflow_env\Lib\site-packages\django\contrib\auth\forms.py", line 366, in clean
    self.user_cache = authenticate(
                      ~~~~~~~~~~~~^
        self.request, username=username, password=password
        ^^^^^^^^^^^^^^^^^^^^^^^^^^^^^^^^^^^^^^^^^^^^^^^^^^
    )
    ^
  File "C:\Users\tefba\Desktop\OverBrand\acadflow\acadflow_env\Lib\site-packages\django\views\decorators\debug.py", line 75, in sensitive_variables_wrapper
    return func(*func_args, **func_kwargs)
  File "C:\Users\tefba\Desktop\OverBrand\acadflow\acadflow_env\Lib\site-packages\django\contrib\auth\__init__.py", line 114, in authenticate
    user = backend.authenticate(request, **credentials)
  File "C:\Users\tefba\Desktop\OverBrand\acadflow\acadflow_env\Lib\site-packages\django\contrib\auth\backends.py", line 65, in authenticate
    user = UserModel._default_manager.get_by_natural_key(username)
  File "C:\Users\tefba\Desktop\OverBrand\acadflow\acadflow_env\Lib\site-packages\django\contrib\auth\base_user.py", line 37, in get_by_natural_key
    return self.get(**{self.model.USERNAME_FIELD: username})
           ~~~~~~~~^^^^^^^^^^^^^^^^^^^^^^^^^^^^^^^^^^^^^^^^^
  File "C:\Users\tefba\Desktop\OverBrand\acadflow\acadflow_env\Lib\site-packages\django\db\models\manager.py", line 87, in manager_method
    return getattr(self.get_queryset(), name)(*args, **kwargs)
           ~~~~~~~~~~~~~~~~~~~~~~~~~~~~~~~~~~^^^^^^^^^^^^^^^^^
  File "C:\Users\tefba\Desktop\OverBrand\acadflow\acadflow_env\Lib\site-packages\django\db\models\query.py", line 629, in get
    num = len(clone)
  File "C:\Users\tefba\Desktop\OverBrand\acadflow\acadflow_env\Lib\site-packages\django\db\models\query.py", line 366, in __len__
    self._fetch_all()
    ~~~~~~~~~~~~~~~^^
  File "C:\Users\tefba\Desktop\OverBrand\acadflow\acadflow_env\Lib\site-packages\django\db\models\query.py", line 1945, in _fetch_all
    self._result_cache = list(self._iterable_class(self))
                         ~~~~^^^^^^^^^^^^^^^^^^^^^^^^^^^^
  File "C:\Users\tefba\Desktop\OverBrand\acadflow\acadflow_env\Lib\site-packages\django\db\models\query.py", line 91, in __iter__
    results = compiler.execute_sql(
        chunked_fetch=self.chunked_fetch, chunk_size=self.chunk_size
    )
  File "C:\Users\tefba\Desktop\OverBrand\acadflow\acadflow_env\Lib\site-packages\django\db\models\sql\compiler.py", line 1623, in execute_sql
    cursor.execute(sql, params)
    ~~~~~~~~~~~~~~^^^^^^^^^^^^^
  File "C:\Users\tefba\Desktop\OverBrand\acadflow\acadflow_env\Lib\site-packages\django\db\backends\utils.py", line 122, in execute
    return super().execute(sql, params)
           ~~~~~~~~~~~~~~~^^^^^^^^^^^^^
  File "C:\Users\tefba\Desktop\OverBrand\acadflow\acadflow_env\Lib\site-packages\django\db\backends\utils.py", line 79, in execute
    return self._execute_with_wrappers(
           ~~~~~~~~~~~~~~~~~~~~~~~~~~~^
        sql, params, many=False, executor=self._execute
        ^^^^^^^^^^^^^^^^^^^^^^^^^^^^^^^^^^^^^^^^^^^^^^^
    )
    ^
  File "C:\Users\tefba\Desktop\OverBrand\acadflow\acadflow_env\Lib\site-packages\django\db\backends\utils.py", line 92, in _execute_with_wrappers
    return executor(sql, params, many, context)
  File "C:\Users\tefba\Desktop\OverBrand\acadflow\acadflow_env\Lib\site-packages\django\db\backends\utils.py", line 100, in _execute
    with self.db.wrap_database_errors:
         ^^^^^^^^^^^^^^^^^^^^^^^^^^^^
  File "C:\Users\tefba\Desktop\OverBrand\acadflow\acadflow_env\Lib\site-packages\django\db\utils.py", line 91, in __exit__
    raise dj_exc_value.with_traceback(traceback) from exc_value
  File "C:\Users\tefba\Desktop\OverBrand\acadflow\acadflow_env\Lib\site-packages\django\db\backends\utils.py", line 105, in _execute
    return self.cursor.execute(sql, params)
           ~~~~~~~~~~~~~~~~~~~^^^^^^^^^^^^^
  File "C:\Users\tefba\Desktop\OverBrand\acadflow\acadflow_env\Lib\site-packages\django\db\backends\sqlite3\base.py", line 360, in execute
    return super().execute(query, params)
           ~~~~~~~~~~~~~~~^^^^^^^^^^^^^^^
django.db.utils.OperationalError: no such table: users
ERROR 2025-06-07 16:37:12,308 basehttp 37916 51372 "POST /admin/login/?next=/admin/ HTTP/1.1" 500 264777
